Workbook

Sheet PASTE-DOWN-DL
C1: 1 | D1: 2 | E1: 3 | F1: 4 | G1: 5 | H1: 6 | I1: 7 | J1: 8 | K1: 9 | L1: 10 | M1: 11 | N1: 12 | O1: 13 | P1: 14 | Q1: 15 | R1: 16 | S1: 17 | T1: 18 | U1: 19 | V1: 20 | W1: 21 | X1: 22 | Y1: 23 | Z1: 24 | AA1: 25 | AB1: 26 | AC1: 27 | AD1: 28 | AE1: 29 | AF1: 30 | AG1: 31 | AH1: 32 | AI1: 33 | AJ1: 34 | AK1: 35 | AL1: 36 | AM1: 37 | AN1: 38 | AO1: 39 | AP1: 40 | AQ1: 41
A2: Don't do any change in GREY colored cells | U2: Paste here --- > CPAN DL FAIL REPORT
AL3: =TEXT(TODAY(),"dd-mm-yyyy") -> 15-05-2026
C4: Down | D4: =MAX(C10:C5000) -> 88 | U4: Choose Days DOWN | V4: 1
C8: 0 | I8: Name | J8: Media Type | K8: Bandwidth | L8: Signal Type | M8: Direction | N8: A End | O8: Z End | P8: Alarm Status | Q8: CIR Utilization Ratio(%) | R8: Bandwidth Utilization Ratio(%) | S8: Order Name | T8: Creator | U8: Client | V8: Cost | W8: Create Time | X8: Update Time | Y8: Description
C9: 0 | D9: ALARM | E9: SSA | F9: SSA TRIM | G9: SSA Sep | H9: Sr | I9: Name | J9: Media Type | K9: Bandwidth | L9: Signal Type | M9: Direction | N9: A End | O9: Z End | P9: Alarm Status | Q9: CIR Utilization Ratio(%) | R9: Bandwidth Utilization Ratio(%) | S9: Order Name | T9: Creator | U9: Client | V9: Cost | W9: Create Time | X9: Update Time | Y9: Description | Z9: DL name TRIM | AA9: A_Srch_ | AB9: A_SrchTN7 | AC9: Z_Srch_ | AD9: Z_SrchTN7 | AE9: A-END IP | AF9: Z-END IP | AG9: A-END Name | AH9: Z-END Name | AI9: A-END Port | AJ9: Z-END port | AK9: DOWN Date | AL9: DOWN time | AM9: A-END MIX | AN9: Z-END MIX | AO9: Down Days | AP9: Date-Time MIX
C10: =IF(D10="Critical",MAX($C$8:C9)+1,"") | D10: =TRIM(CLEAN(P10)) -> - | E10: =VLOOKUP('PASTE-DOWN-DL'!F10,'SSA-CODE'!$D$4:$E$56,2,FALSE) -> AHD | F10: =TRIM(CLEAN(SUBSTITUTE(G10,CHAR(160)," "))) -> SSA AM | G10: =MID(I10,1,SEARCH("-",I10)-1) -> SSA AM | H10: 1 | I10: SSA AM-10.121.18.249-Sector24_3/1-10.121.18.245-Sector11_3/1 | J10: Fiber | K10: 10GE | L10: Eth | M10: BI-DIR | N10: 10.121.18.245_SECTOR 11 GNE_TN725B_GJ_SSA AM_PH1\S3P1 | O10: 10.121.18.249_SECTOR 24_TN725B_GJ_SSA AM_PH3\S3P1 | P10: - | Q10: 34 | R10: 54 | T10: kanishk | V10: 1.0 | W10: 2019/05/20,18:42:34 | X10: 2026/04/18,11:21:46 | Z10: =TRIM(CLEAN(I10)) -> SSA AM-10.121.18.249-Sector24_3/1-10.121.18.245-Sector11_3/1 | AA10: =SEARCH("_",N10) -> 15 | AB10: =SEARCH("_TN7",N10) -> 29 | AC10: =SEARCH("_",O10) -> 15 | AD10: =SEARCH("_TN7",O10) -> 25 | AE10: =TRIM(CLEAN(MID(N10,1,SEARCH("_",N10)-1))) -> 10.121.18.245 | AF10: =TRIM(CLEAN(MID(O10,1,SEARCH("_",O10)-1))) -> 10.121.18.249 | AG10: =MID(N10,AA10+1,AB10-AA10-1) -> SECTOR 11 GNE | AH10: =MID(O10,AC10+1,AD10-AC10-1) -> SECTOR 24 | AI10: =RIGHT(N10,LEN(N10)-SEARCH("\",N10)) -> S3P1 | AJ10: =RIGHT(O10,LEN(O10)-SEARCH("\",O10)) -> S3P1 | AK10: =IFERROR(VLOOKUP(Z10,'PASTE-DL-ALARMS'!$Q$10:$W$2200,7,FALSE),"") | AL10: =IFERROR(VLOOKUP(Z10,'PASTE-DL-ALARMS'!$Q$10:$W$2200,3,FALSE),"") | AM10: =CONCATENATE(AE10,"_",AG10,"_",AI10) -> 10.121.18.245_SECTOR 11 GNE_S3P1 | AN10: =CONCATENATE(AF10,"_",AH10,"_",AJ10) -> 10.121.18.249_SECTOR 24_S3P1 | AO10: =$AL$3-AK10 -> #VALUE! | AP10: =IFERROR(VLOOKUP(Z10,'PASTE-DL-ALARMS'!$Q$10:$Z$2800,8,FALSE),"")
C11: =IF(D11="Critical",MAX($C$8:C10)+1,"") | D11: =TRIM(CLEAN(P11)) -> - | E11: =VLOOKUP('PASTE-DOWN-DL'!F11,'SSA-CODE'!$D$4:$E$56,2,FALSE) -> BCH | F11: =TRIM(CLEAN(SUBSTITUTE(G11,CHAR(160)," "))) -> SSA BCH | G11: =MID(I11,1,SEARCH("-",I11)-1) -> SSA BCH | H11: 2 | I11: SSA BCH-10.121.96.93-Grasim Chem Vilayat_2/5-10.121.96.94-Grasim Fibre Vilayat_1/5 | J11: Fiber | K11: GE | L11: Eth | M11: BI-DIR | N11: 10.121.96.93_Grasim Chem Vilayat_TN703B_GJ_SSA BCH_PH3\S2P5 | O11: 10.121.96.94_Grasim Fibre Vilayat_TN703B_GJ_SSA BCH_PH3\S1P5 | P11: - | Q11: 30 | R11: 100 | T11: kanishk | V11: 1.0 | W11: 2019/05/31,17:05:32 | X11: 2026/04/14,14:19:13 | Z11: =TRIM(CLEAN(I11)) -> SSA BCH-10.121.96.93-Grasim Chem Vilayat_2/5-10.121.96.94-Grasim Fibre Vilayat_1/5 | AA11: =SEARCH("_",N11) -> 14 | AB11: =SEARCH("_TN7",N11) -> 34 | AC11: =SEARCH("_",O11) -> 14 | AD11: =SEARCH("_TN7",O11) -> 35 | AE11: =TRIM(CLEAN(MID(N11,1,SEARCH("_",N11)-1))) -> 10.121.96.93 | AF11: =TRIM(CLEAN(MID(O11,1,SEARCH("_",O11)-1))) -> 10.121.96.94 | AG11: =MID(N11,AA11+1,AB11-AA11-1) -> Grasim Chem Vilayat | AH11: =MID(O11,AC11+1,AD11-AC11-1) -> Grasim Fibre Vilayat | AI11: =RIGHT(N11,LEN(N11)-SEARCH("\",N11)) -> S2P5 | AJ11: =RIGHT(O11,LEN(O11)-SEARCH("\",O11)) -> S1P5 | AK11: =IFERROR(VLOOKUP(Z11,'PASTE-DL-ALARMS'!$Q$10:$W$2200,7,FALSE),"") | AL11: =IFERROR(VLOOKUP(Z11,'PASTE-DL-ALARMS'!$Q$10:$W$2200,3,FALSE),"") | AM11: =CONCATENATE(AE11,"_",AG11,"_",AI11) -> 10.121.96.93_Grasim Chem Vilayat_S2P5 | AN11: =CONCATENATE(AF11,"_",AH11,"_",AJ11) -> 10.121.96.94_Grasim Fibre Vilayat_S1P5 | AO11: =$AL$3-AK11 -> #VALUE! | AP11: =IFERROR(VLOOKUP(Z11,'PASTE-DL-ALARMS'!$Q$10:$Z$2800,8,FALSE),"")
C12: =IF(D12="Critical",MAX($C$8:C11)+1,"") | D12: =TRIM(CLEAN(P12)) -> - | E12: =VLOOKUP('PASTE-DOWN-DL'!F12,'SSA-CODE'!$D$4:$E$56,2,FALSE) -> VAL | F12: =TRIM(CLEAN(SUBSTITUTE(G12,CHAR(160)," "))) -> SSA VAL | G12: =MID(I12,1,SEARCH("-",I12)-1) -> SSA VAL | H12: 3 | I12: SSA VAL-10.121.68.67-Silvassa_6/3-10.121.68.80-NIC-Silvassa_1/5 | J12: Fiber | K12: GE | L12: Eth | M12: BI-DIR | N12: 10.121.68.80_NIC Silvassa_TN703B_GJ_SSA VAL_PH2\S1P5 | O12: 10.121.68.67_Silvassa_TN725B_WTR_AM_PH3\S6P3 | P12: - | Q12: 68 | R12: 100 | S12: VALSAD SSA | T12: minaxikataria | U12: GCS ISSUE ID : 26139 | V12: 1.0 | W12: 2023/10/05,18:43:37 | X12: 2026/04/18,11:22:35 | Z12: =TRIM(CLEAN(I12)) -> SSA VAL-10.121.68.67-Silvassa_6/3-10.121.68.80-NIC-Silvassa_1/5 | AA12: =SEARCH("_",N12) -> 14 | AB12: =SEARCH("_TN7",N12) -> 27 | AC12: =SEARCH("_",O12) -> 14 | AD12: =SEARCH("_TN7",O12) -> 23 | AE12: =TRIM(CLEAN(MID(N12,1,SEARCH("_",N12)-1))) -> 10.121.68.80 | AF12: =TRIM(CLEAN(MID(O12,1,SEARCH("_",O12)-1))) -> 10.121.68.67 | AG12: =MID(N12,AA12+1,AB12-AA12-1) -> NIC Silvassa | AH12: =MID(O12,AC12+1,AD12-AC12-1) -> Silvassa | AI12: =RIGHT(N12,LEN(N12)-SEARCH("\",N12)) -> S1P5 | AJ12: =RIGHT(O12,LEN(O12)-SEARCH("\",O12)) -> S6P3 | AK12: =IFERROR(VLOOKUP(Z12,'PASTE-DL-ALARMS'!$Q$10:$W$2200,7,FALSE),"") | AL12: =IFERROR(VLOOKUP(Z12,'PASTE-DL-ALARMS'!$Q$10:$W$2200,3,FALSE),"") | AM12: =CONCATENATE(AE12,"_",AG12,"_",AI12) -> 10.121.68.80_NIC Silvassa_S1P5 | AN12: =CONCATENATE(AF12,"_",AH12,"_",AJ12) -> 10.121.68.67_Silvassa_S6P3 | AO12: =$AL$3-AK12 -> #VALUE! | AP12: =IFERROR(VLOOKUP(Z12,'PASTE-DL-ALARMS'!$Q$10:$Z$2800,8,FALSE),"")
C13: =IF(D13="Critical",MAX($C$8:C12)+1,"") | D13: =TRIM(CLEAN(P13)) -> - | E13: =VLOOKUP('PASTE-DOWN-DL'!F13,'SSA-CODE'!$D$4:$E$56,2,FALSE) -> AMR | F13: =TRIM(CLEAN(SUBSTITUTE(G13,CHAR(160)," "))) -> SSA AMR | G13: =MID(I13,1,SEARCH("-",I13)-1) -> SSA AMR | H13: 4 | I13: SSA AMR-10.121.96.26-SVU_GswanTC_2/6-10.121.96.11-KUP_Exch_4/2 | J13: Fiber | K13: GE | L13: Eth | M13: BI-DIR | N13: 10.121.96.26_SVU GSWAN TC_TN703B_GJ_SSA AMR_PH2\S2P6 | O13: 10.121.96.11_KUP EXCH_TN705B_GJ_SSA AMR_PH3\S4P2 | P13: - | Q13: 96 | R13: 100 | T13: 198505975 | U13: GujAmreli_SSA | V13: 1.0 | W13: 2019/11/05,11:09:21 | X13: 2026/04/18,11:23:10 | Z13: =TRIM(CLEAN(I13)) -> SSA AMR-10.121.96.26-SVU_GswanTC_2/6-10.121.96.11-KUP_Exch_4/2 | AA13: =SEARCH("_",N13) -> 14 | AB13: =SEARCH("_TN7",N13) -> 27 | AC13: =SEARCH("_",O13) -> 14 | AD13: =SEARCH("_TN7",O13) -> 23 | AE13: =TRIM(CLEAN(MID(N13,1,SEARCH("_",N13)-1))) -> 10.121.96.26 | AF13: =TRIM(CLEAN(MID(O13,1,SEARCH("_",O13)-1))) -> 10.121.96.11 | AG13: =MID(N13,AA13+1,AB13-AA13-1) -> SVU GSWAN TC | AH13: =MID(O13,AC13+1,AD13-AC13-1) -> KUP EXCH | AI13: =RIGHT(N13,LEN(N13)-SEARCH("\",N13)) -> S2P6 | AJ13: =RIGHT(O13,LEN(O13)-SEARCH("\",O13)) -> S4P2 | AK13: =IFERROR(VLOOKUP(Z13,'PASTE-DL-ALARMS'!$Q$10:$W$2200,7,FALSE),"") | AL13: =IFERROR(VLOOKUP(Z13,'PASTE-DL-ALARMS'!$Q$10:$W$2200,3,FALSE),"") | AM13: =CONCATENATE(AE13,"_",AG13,"_",AI13) -> 10.121.96.26_SVU GSWAN TC_S2P6 | AN13: =CONCATENATE(AF13,"_",AH13,"_",AJ13) -> 10.121.96.11_KUP EXCH_S4P2 | AO13: =$AL$3-AK13 -> #VALUE! | AP13: =IFERROR(VLOOKUP(Z13,'PASTE-DL-ALARMS'!$Q$10:$Z$2800,8,FALSE),"")
C14: =IF(D14="Critical",MAX($C$8:C13)+1,"") | D14: =TRIM(CLEAN(P14)) -> - | E14: =VLOOKUP('PASTE-DOWN-DL'!F14,'SSA-CODE'!$D$4:$E$56,2,FALSE) -> GDR | F14: =TRIM(CLEAN(SUBSTITUTE(G14,CHAR(160)," "))) -> SSA GDH | G14: =MID(I14,1,SEARCH("-",I14)-1) -> SSA GDH | H14: 5 | I14: SSA GDH-10.121.19.16-Nandarva_1/5-10.121.16.195-Sehra_3/2 | J14: Fiber | K14: GE | L14: Eth | M14: BI-DIR | N14: 10.121.19.16_Nandarva_TN703B_GJ_SSA GDH_PH3\S1P5 | O14: 10.121.16.195_Sehra_TN705B_WTR_AM_PH1\S3P2 | P14: - | Q14: 18 | R14: 100 | S14: Godhra_SSA_GCS_ID_15148 | T14: 199105665 | U14: Godhra_SSA | V14: 1.0 | W14: 2022/03/07,15:19:22 | X14: 2026/04/18,11:23:33 | Z14: =TRIM(CLEAN(I14)) -> SSA GDH-10.121.19.16-Nandarva_1/5-10.121.16.195-Sehra_3/2 | AA14: =SEARCH("_",N14) -> 14 | AB14: =SEARCH("_TN7",N14) -> 23 | AC14: =SEARCH("_",O14) -> 15 | AD14: =SEARCH("_TN7",O14) -> 21 | AE14: =TRIM(CLEAN(MID(N14,1,SEARCH("_",N14)-1))) -> 10.121.19.16 | AF14: =TRIM(CLEAN(MID(O14,1,SEARCH("_",O14)-1))) -> 10.121.16.195 | AG14: =MID(N14,AA14+1,AB14-AA14-1) -> Nandarva | AH14: =MID(O14,AC14+1,AD14-AC14-1) -> Sehra | AI14: =RIGHT(N14,LEN(N14)-SEARCH("\",N14)) -> S1P5 | AJ14: =RIGHT(O14,LEN(O14)-SEARCH("\",O14)) -> S3P2 | AK14: =IFERROR(VLOOKUP(Z14,'PASTE-DL-ALARMS'!$Q$10:$W$2200,7,FALSE),"") | AL14: =IFERROR(VLOOKUP(Z14,'PASTE-DL-ALARMS'!$Q$10:$W$2200,3,FALSE),"") | AM14: =CONCATENATE(AE14,"_",AG14,"_",AI14) -> 10.121.19.16_Nandarva_S1P5 | AN14: =CONCATENATE(AF14,"_",AH14,"_",AJ14) -> 10.121.16.195_Sehra_S3P2 | AO14: =$AL$3-AK14 -> #VALUE! | AP14: =IFERROR(VLOOKUP(Z14,'PASTE-DL-ALARMS'!$Q$10:$Z$2800,8,FALSE),"")
C15: =IF(D15="Critical",MAX($C$8:C14)+1,"") | D15: =TRIM(CLEAN(P15)) -> - | E15: =VLOOKUP('PASTE-DOWN-DL'!F15,'SSA-CODE'!$D$4:$E$56,2,FALSE) -> BHV | F15: =TRIM(CLEAN(SUBSTITUTE(G15,CHAR(160)," "))) -> SSA BV | G15: =MID(I15,1,SEARCH("-",I15)-1) -> SSA BV | H15: 6 | I15: SSA BV-10.121.17.165-Tana_2/5-10.121.17.164-Madhada_3/2 | J15: Fiber | K15: GE | L15: Eth | M15: BI-DIR | N15: 10.121.17.165_Tana_TN703B_GJ_SSA BV_PH3\S2P5 | O15: 10.121.17.164_MADHADA_TN705B_GJ_SSA BV_PH3\S3P2 | P15: - | Q15: 31 | R15: 100 | S15: Bhavnagar SSA GCS ID 40918 | T15: 200800716 | U15: Bhavnagar SSA GCS ID 40918 | V15: 1.0 | W15: 2025/04/19,18:19:56 | X15: 2026/04/02,13:10:43 | Z15: =TRIM(CLEAN(I15)) -> SSA BV-10.121.17.165-Tana_2/5-10.121.17.164-Madhada_3/2 | AA15: =SEARCH("_",N15) -> 15 | AB15: =SEARCH("_TN7",N15) -> 20 | AC15: =SEARCH("_",O15) -> 15 | AD15: =SEARCH("_TN7",O15) -> 23 | AE15: =TRIM(CLEAN(MID(N15,1,SEARCH("_",N15)-1))) -> 10.121.17.165 | AF15: =TRIM(CLEAN(MID(O15,1,SEARCH("_",O15)-1))) -> 10.121.17.164 | AG15: =MID(N15,AA15+1,AB15-AA15-1) -> Tana | AH15: =MID(O15,AC15+1,AD15-AC15-1) -> MADHADA | AI15: =RIGHT(N15,LEN(N15)-SEARCH("\",N15)) -> S2P5 | AJ15: =RIGHT(O15,LEN(O15)-SEARCH("\",O15)) -> S3P2 | AK15: =IFERROR(VLOOKUP(Z15,'PASTE-DL-ALARMS'!$Q$10:$W$2200,7,FALSE),"") | AL15: =IFERROR(VLOOKUP(Z15,'PASTE-DL-ALARMS'!$Q$10:$W$2200,3,FALSE),"") | AM15: =CONCATENATE(AE15,"_",AG15,"_",AI15) -> 10.121.17.165_Tana_S2P5 | AN15: =CONCATENATE(AF15,"_",AH15,"_",AJ15) -> 10.121.17.164_MADHADA_S3P2 | AO15: =$AL$3-AK15 -> #VALUE! | AP15: =IFERROR(VLOOKUP(Z15,'PASTE-DL-ALARMS'!$Q$10:$Z$2800,8,FALSE),"")
C16: =IF(D16="Critical",MAX($C$8:C15)+1,"") | D16: =TRIM(CLEAN(P16)) -> - | E16: =VLOOKUP('PASTE-DOWN-DL'!F16,'SSA-CODE'!$D$4:$E$56,2,FALSE) -> JND | F16: =TRIM(CLEAN(SUBSTITUTE(G16,CHAR(160)," "))) -> SSA JND | G16: =MID(I16,1,SEARCH("-",I16)-1) -> SSA JND | H16: 7 | I16: SSA JND-10.121.24.10-Somnath_1/5-10.121.24.25-GIDC VRL_1/5 | J16: Fiber | K16: GE | L16: Eth | M16: BI-DIR | N16: 10.121.24.10_SOMNATH_TN703B_GJ_SSA JND_PH2\S1P5 | O16: 10.121.24.25_GIDC VRL_TN703B_GJ_SSA JND_PH2\S1P5 | P16: - | Q16: 58 | R16: 100 | S16: Guj GCS ID: 035941 | T16: 200700547 | U16: Guj GCS ID: 035941 | V16: 1.0 | W16: 2024/11/20,16:23:53 | X16: 2026/04/02,13:11:21 | Z16: =TRIM(CLEAN(I16)) -> SSA JND-10.121.24.10-Somnath_1/5-10.121.24.25-GIDC VRL_1/5 | AA16: =SEARCH("_",N16) -> 14 | AB16: =SEARCH("_TN7",N16) -> 22 | AC16: =SEARCH("_",O16) -> 14 | AD16: =SEARCH("_TN7",O16) -> 23 | AE16: =TRIM(CLEAN(MID(N16,1,SEARCH("_",N16)-1))) -> 10.121.24.10 | AF16: =TRIM(CLEAN(MID(O16,1,SEARCH("_",O16)-1))) -> 10.121.24.25 | AG16: =MID(N16,AA16+1,AB16-AA16-1) -> SOMNATH | AH16: =MID(O16,AC16+1,AD16-AC16-1) -> GIDC VRL | AI16: =RIGHT(N16,LEN(N16)-SEARCH("\",N16)) -> S1P5 | AJ16: =RIGHT(O16,LEN(O16)-SEARCH("\",O16)) -> S1P5 | AK16: =IFERROR(VLOOKUP(Z16,'PASTE-DL-ALARMS'!$Q$10:$W$2200,7,FALSE),"") | AL16: =IFERROR(VLOOKUP(Z16,'PASTE-DL-ALARMS'!$Q$10:$W$2200,3,FALSE),"") | AM16: =CONCATENATE(AE16,"_",AG16,"_",AI16) -> 10.121.24.10_SOMNATH_S1P5 | AN16: =CONCATENATE(AF16,"_",AH16,"_",AJ16) -> 10.121.24.25_GIDC VRL_S1P5 | AO16: =$AL$3-AK16 -> #VALUE! | AP16: =IFERROR(VLOOKUP(Z16,'PASTE-DL-ALARMS'!$Q$10:$Z$2800,8,FALSE),"")
C17: =IF(D17="Critical",MAX($C$8:C16)+1,"") | D17: =TRIM(CLEAN(P17)) -> - | E17: =VLOOKUP('PASTE-DOWN-DL'!F17,'SSA-CODE'!$D$4:$E$56,2,FALSE) -> GDR | F17: =TRIM(CLEAN(SUBSTITUTE(G17,CHAR(160)," "))) -> SSA GDH | G17: =MID(I17,1,SEARCH("-",I17)-1) -> SSA GDH | H17: 8 | I17: SSA GDH-10.121.16.228-Godhra2_6/1-10.121.26.65-Godhra(GNE)_6/1 | J17: Fiber | K17: 10GE | L17: Eth | M17: BI-DIR | N17: 10.121.16.228_Godhra 2_TN725B_WTR_AM_PH1\S6P1 | O17: 10.121.26.65_Godhra (GNE)_TN725B_WTR_AM_PH2\S6P1 | P17: - | Q17: 75 | R17: 100 | S17: Godhra SSA | T17: minaxikataria | U17: GCS Issue id : 19925 | V17: 1.0 | W17: 2022/11/14,12:34:25 | X17: 2026/04/18,11:24:25 | Z17: =TRIM(CLEAN(I17)) -> SSA GDH-10.121.16.228-Godhra2_6/1-10.121.26.65-Godhra(GNE)_6/1 | AA17: =SEARCH("_",N17) -> 15 | AB17: =SEARCH("_TN7",N17) -> 24 | AC17: =SEARCH("_",O17) -> 14 | AD17: =SEARCH("_TN7",O17) -> 27 | AE17: =TRIM(CLEAN(MID(N17,1,SEARCH("_",N17)-1))) -> 10.121.16.228 | AF17: =TRIM(CLEAN(MID(O17,1,SEARCH("_",O17)-1))) -> 10.121.26.65 | AG17: =MID(N17,AA17+1,AB17-AA17-1) -> Godhra 2 | AH17: =MID(O17,AC17+1,AD17-AC17-1) -> Godhra (GNE) | AI17: =RIGHT(N17,LEN(N17)-SEARCH("\",N17)) -> S6P1 | AJ17: =RIGHT(O17,LEN(O17)-SEARCH("\",O17)) -> S6P1 | AK17: =IFERROR(VLOOKUP(Z17,'PASTE-DL-ALARMS'!$Q$10:$W$2200,7,FALSE),"") | AL17: =IFERROR(VLOOKUP(Z17,'PASTE-DL-ALARMS'!$Q$10:$W$2200,3,FALSE),"") | AM17: =CONCATENATE(AE17,"_",AG17,"_",AI17) -> 10.121.16.228_Godhra 2_S6P1 | AN17: =CONCATENATE(AF17,"_",AH17,"_",AJ17) -> 10.121.26.65_Godhra (GNE)_S6P1 | AO17: =$AL$3-AK17 -> #VALUE! | AP17: =IFERROR(VLOOKUP(Z17,'PASTE-DL-ALARMS'!$Q$10:$Z$2800,8,FALSE),"")
C18: =IF(D18="Critical",MAX($C$8:C17)+1,"") | D18: =TRIM(CLEAN(P18)) -> - | E18: =VLOOKUP('PASTE-DOWN-DL'!F18,'SSA-CODE'!$D$4:$E$56,2,FALSE) -> JMN | F18: =TRIM(CLEAN(SUBSTITUTE(G18,CHAR(160)," "))) -> SSA JMN | G18: =MID(I18,1,SEARCH("-",I18)-1) -> SSA JMN | H18: 9 | I18: SSA JMN-10.121.97.129-Mehulnagar ALB_6/4-10.121.20.1-Mehul Nagar(GNE)_6/4 | J18: Fiber | K18: GE | L18: Eth | M18: BI-DIR | N18: 10.121.97.129_Mehulnagar ALB_TN725B_GJ_SSA JMN_PH3\S6P4 | O18: 10.121.20.1_Mehul Nagar(GNE)_TN725B_GJ_SSA JMN_PH2\S6P4 | P18: - | Q18: 70 | R18: 100 | S18: Guj GCS ID No.- 044941 | T18: 200700547 | U18: SSA Jamnagar | V18: 1.0 | W18: 2025/09/11,12:38:46 | X18: 2026/04/02,13:12:32 | Z18: =TRIM(CLEAN(I18)) -> SSA JMN-10.121.97.129-Mehulnagar ALB_6/4-10.121.20.1-Mehul Nagar(GNE)_6/4 | AA18: =SEARCH("_",N18) -> 15 | AB18: =SEARCH("_TN7",N18) -> 30 | AC18: =SEARCH("_",O18) -> 13 | AD18: =SEARCH("_TN7",O18) -> 30 | AE18: =TRIM(CLEAN(MID(N18,1,SEARCH("_",N18)-1))) -> 10.121.97.129 | AF18: =TRIM(CLEAN(MID(O18,1,SEARCH("_",O18)-1))) -> 10.121.20.1 | AG18: =MID(N18,AA18+1,AB18-AA18-1) -> Mehulnagar ALB | AH18: =MID(O18,AC18+1,AD18-AC18-1) -> Mehul Nagar(GNE) | AI18: =RIGHT(N18,LEN(N18)-SEARCH("\",N18)) -> S6P4 | AJ18: =RIGHT(O18,LEN(O18)-SEARCH("\",O18)) -> S6P4 | AK18: =IFERROR(VLOOKUP(Z18,'PASTE-DL-ALARMS'!$Q$10:$W$2200,7,FALSE),"") | AL18: =IFERROR(VLOOKUP(Z18,'PASTE-DL-ALARMS'!$Q$10:$W$2200,3,FALSE),"") | AM18: =CONCATENATE(AE18,"_",AG18,"_",AI18) -> 10.121.97.129_Mehulnagar ALB_S6P4 | AN18: =CONCATENATE(AF18,"_",AH18,"_",AJ18) -> 10.121.20.1_Mehul Nagar(GNE)_S6P4 | AO18: =$AL$3-AK18 -> #VALUE! | AP18: =IFERROR(VLOOKUP(Z18,'PASTE-DL-ALARMS'!$Q$10:$Z$2800,8,FALSE),"")
C19: =IF(D19="Critical",MAX($C$8:C18)+1,"") | D19: =TRIM(CLEAN(P19)) -> - | E19: =VLOOKUP('PASTE-DOWN-DL'!F19,'SSA-CODE'!$D$4:$E$56,2,FALSE) -> BUJ | F19: =TRIM(CLEAN(SUBSTITUTE(G19,CHAR(160)," "))) -> SSA BUJ | G19: =MID(I19,1,SEARCH("-",I19)-1) -> SSA BUJ | H19: 10 | I19: SSA BUJ-10.121.96.156-Mata_na_Madh_1/5-10.121.96.137-Dayapar_4/3 | J19: Fiber | K19: GE | L19: Eth | M19: BI-DIR | N19: 10.121.96.137_Dayapar_TN705B_GJ_SSA BUJ_PH3\S4P3 | O19: 10.121.96.156_MATA NA MADH_TN703B_GJ_SSA BUJ_PH2\S1P5 | P19: - | Q19: 36 | R19: 100 | S19: Bhuj SSA - GCS ID-0002860 | T19: ritesh | U19: Bhuj SSA | V19: 1.0 | W19: 2019/07/09,18:40:33 | X19: 2026/04/18,11:25:02 | Z19: =TRIM(CLEAN(I19)) -> SSA BUJ-10.121.96.156-Mata_na_Madh_1/5-10.121.96.137-Dayapar_4/3 | AA19: =SEARCH("_",N19) -> 15 | AB19: =SEARCH("_TN7",N19) -> 23 | AC19: =SEARCH("_",O19) -> 15 | AD19: =SEARCH("_TN7",O19) -> 28 | AE19: =TRIM(CLEAN(MID(N19,1,SEARCH("_",N19)-1))) -> 10.121.96.137 | AF19: =TRIM(CLEAN(MID(O19,1,SEARCH("_",O19)-1))) -> 10.121.96.156 | AG19: =MID(N19,AA19+1,AB19-AA19-1) -> Dayapar | AH19: =MID(O19,AC19+1,AD19-AC19-1) -> MATA NA MADH | AI19: =RIGHT(N19,LEN(N19)-SEARCH("\",N19)) -> S4P3 | AJ19: =RIGHT(O19,LEN(O19)-SEARCH("\",O19)) -> S1P5 | AK19: =IFERROR(VLOOKUP(Z19,'PASTE-DL-ALARMS'!$Q$10:$W$2200,7,FALSE),"") | AL19: =IFERROR(VLOOKUP(Z19,'PASTE-DL-ALARMS'!$Q$10:$W$2200,3,FALSE),"") | AM19: =CONCATENATE(AE19,"_",AG19,"_",AI19) -> 10.121.96.137_Dayapar_S4P3 | AN19: =CONCATENATE(AF19,"_",AH19,"_",AJ19) -> 10.121.96.156_MATA NA MADH_S1P5 | AO19: =$AL$3-AK19 -> #VALUE! | AP19: =IFERROR(VLOOKUP(Z19,'PASTE-DL-ALARMS'!$Q$10:$Z$2800,8,FALSE),"")
C20: =IF(D20="Critical",MAX($C$8:C19)+1,"") | D20: =TRIM(CLEAN(P20)) -> - | E20: =VLOOKUP('PASTE-DOWN-DL'!F20,'SSA-CODE'!$D$4:$E$56,2,FALSE) -> BUJ | F20: =TRIM(CLEAN(SUBSTITUTE(G20,CHAR(160)," "))) -> SSA BUJ | G20: =MID(I20,1,SEARCH("-",I20)-1) -> SSA BUJ | H20: 11 | I20: SSA BUJ-10.121.24.67-Gandhidham_4/4-10.121.17.69-Gandhidham_4/5 | J20: Fiber | K20: GE | L20: Eth | M20: BI-DIR | N20: 10.121.24.67_Gandhidham_TN725B_GJ_SSA BUJ_PH2\S4P4 | O20: 10.121.17.69_GANDHIDHAM_TN725B_WTR_RJ_PH1\S4P5 | P20: - | Q20: 53 | R20: 100 | S20: Bhuj SSA | T20: vishleshpatel | U20: Bhuj SSA | V20: 1.0 | W20: 2019/03/11,16:45:48 | X20: 2025/02/22,12:38:23 | Z20: =TRIM(CLEAN(I20)) -> SSA BUJ-10.121.24.67-Gandhidham_4/4-10.121.17.69-Gandhidham_4/5 | AA20: =SEARCH("_",N20) -> 14 | AB20: =SEARCH("_TN7",N20) -> 25 | AC20: =SEARCH("_",O20) -> 14 | AD20: =SEARCH("_TN7",O20) -> 25 | AE20: =TRIM(CLEAN(MID(N20,1,SEARCH("_",N20)-1))) -> 10.121.24.67 | AF20: =TRIM(CLEAN(MID(O20,1,SEARCH("_",O20)-1))) -> 10.121.17.69 | AG20: =MID(N20,AA20+1,AB20-AA20-1) -> Gandhidham | AH20: =MID(O20,AC20+1,AD20-AC20-1) -> GANDHIDHAM | AI20: =RIGHT(N20,LEN(N20)-SEARCH("\",N20)) -> S4P4 | AJ20: =RIGHT(O20,LEN(O20)-SEARCH("\",O20)) -> S4P5 | AK20: =IFERROR(VLOOKUP(Z20,'PASTE-DL-ALARMS'!$Q$10:$W$2200,7,FALSE),"") | AL20: =IFERROR(VLOOKUP(Z20,'PASTE-DL-ALARMS'!$Q$10:$W$2200,3,FALSE),"") | AM20: =CONCATENATE(AE20,"_",AG20,"_",AI20) -> 10.121.24.67_Gandhidham_S4P4 | AN20: =CONCATENATE(AF20,"_",AH20,"_",AJ20) -> 10.121.17.69_GANDHIDHAM_S4P5 | AO20: =$AL$3-AK20 -> #VALUE! | AP20: =IFERROR(VLOOKUP(Z20,'PASTE-DL-ALARMS'!$Q$10:$Z$2800,8,FALSE),"")
C21: =IF(D21="Critical",MAX($C$8:C20)+1,"") | D21: =TRIM(CLEAN(P21)) -> - | E21: =VLOOKUP('PASTE-DOWN-DL'!F21,'SSA-CODE'!$D$4:$E$56,2,FALSE) -> SEN | F21: =TRIM(CLEAN(SUBSTITUTE(G21,CHAR(160)," "))) -> SSA SEN | G21: =MID(I21,1,SEARCH("-",I21)-1) -> SSA SEN | H21: 12 | I21: SSA SEN-10.121.99.31-Vana_3/1-10.121.99.38-Patdi_3/1-10GE | J21: Fiber | K21: 10GE | L21: Eth | M21: BI-DIR | N21: 10.121.99.31_VANA_TN705B_GJ_SSA SEN_PH3\S3P1 | O21: 10.121.99.38_PATDI_TN705B_WTR_RJ_PH1\S3P1 | P21: - | Q21: 18 | R21: 27 | S21: Surendranagar_SSA_GCS_Id_0007086 | T21: 199105665 | U21: Surendranagar_SSA | V21: 1.0 | W21: 2024/08/26,14:46:00 | X21: 2026/04/18,11:26:42 | Z21: =TRIM(CLEAN(I21)) -> SSA SEN-10.121.99.31-Vana_3/1-10.121.99.38-Patdi_3/1-10GE | AA21: =SEARCH("_",N21) -> 14 | AB21: =SEARCH("_TN7",N21) -> 19 | AC21: =SEARCH("_",O21) -> 14 | AD21: =SEARCH("_TN7",O21) -> 20 | AE21: =TRIM(CLEAN(MID(N21,1,SEARCH("_",N21)-1))) -> 10.121.99.31 | AF21: =TRIM(CLEAN(MID(O21,1,SEARCH("_",O21)-1))) -> 10.121.99.38 | AG21: =MID(N21,AA21+1,AB21-AA21-1) -> VANA | AH21: =MID(O21,AC21+1,AD21-AC21-1) -> PATDI | AI21: =RIGHT(N21,LEN(N21)-SEARCH("\",N21)) -> S3P1 | AJ21: =RIGHT(O21,LEN(O21)-SEARCH("\",O21)) -> S3P1 | AK21: =IFERROR(VLOOKUP(Z21,'PASTE-DL-ALARMS'!$Q$10:$W$2200,7,FALSE),"") | AL21: =IFERROR(VLOOKUP(Z21,'PASTE-DL-ALARMS'!$Q$10:$W$2200,3,FALSE),"") | AM21: =CONCATENATE(AE21,"_",AG21,"_",AI21) -> 10.121.99.31_VANA_S3P1 | AN21: =CONCATENATE(AF21,"_",AH21,"_",AJ21) -> 10.121.99.38_PATDI_S3P1 | AO21: =$AL$3-AK21 -> #VALUE! | AP21: =IFERROR(VLOOKUP(Z21,'PASTE-DL-ALARMS'!$Q$10:$Z$2800,8,FALSE),"")
C22: =IF(D22="Critical",MAX($C$8:C21)+1,"") | D22: =TRIM(CLEAN(P22)) -> - | E22: =VLOOKUP('PASTE-DOWN-DL'!F22,'SSA-CODE'!$D$4:$E$56,2,FALSE) -> SRT | F22: =TRIM(CLEAN(SUBSTITUTE(G22,CHAR(160)," "))) -> SSA SR | G22: =MID(I22,1,SEARCH("-",I22)-1) -> SSA SR | H22: 13 | I22: SSA SR-10.121.19.213-GETCO_ICHP_3/1-10.121.19.199-Rundh_5/1 | J22: Fiber | K22: 10GE | L22: Eth | M22: BI-DIR | N22: 10.121.19.199_RUNDH_TN725B_GJ_SSA SR_PH2\S5P1 | O22: 10.121.19.213_GETCO ICHP_TN705B_GJ_SSA SR_PH3\S3P1 | P22: - | Q22: 39 | R22: 59 | S22: GCS ID 37455 | T22: 200800022 | U22: SURAT SSA | V22: 1.0 | W22: 2025/07/16,16:20:54 | X22: 2026/04/18,11:27:22 | Z22: =TRIM(CLEAN(I22)) -> SSA SR-10.121.19.213-GETCO_ICHP_3/1-10.121.19.199-Rundh_5/1 | AA22: =SEARCH("_",N22) -> 15 | AB22: =SEARCH("_TN7",N22) -> 21 | AC22: =SEARCH("_",O22) -> 15 | AD22: =SEARCH("_TN7",O22) -> 26 | AE22: =TRIM(CLEAN(MID(N22,1,SEARCH("_",N22)-1))) -> 10.121.19.199 | AF22: =TRIM(CLEAN(MID(O22,1,SEARCH("_",O22)-1))) -> 10.121.19.213 | AG22: =MID(N22,AA22+1,AB22-AA22-1) -> RUNDH | AH22: =MID(O22,AC22+1,AD22-AC22-1) -> GETCO ICHP | AI22: =RIGHT(N22,LEN(N22)-SEARCH("\",N22)) -> S5P1 | AJ22: =RIGHT(O22,LEN(O22)-SEARCH("\",O22)) -> S3P1 | AK22: =IFERROR(VLOOKUP(Z22,'PASTE-DL-ALARMS'!$Q$10:$W$2200,7,FALSE),"") | AL22: =IFERROR(VLOOKUP(Z22,'PASTE-DL-ALARMS'!$Q$10:$W$2200,3,FALSE),"") | AM22: =CONCATENATE(AE22,"_",AG22,"_",AI22) -> 10.121.19.199_RUNDH_S5P1 | AN22: =CONCATENATE(AF22,"_",AH22,"_",AJ22) -> 10.121.19.213_GETCO ICHP_S3P1 | AO22: =$AL$3-AK22 -> #VALUE! | AP22: =IFERROR(VLOOKUP(Z22,'PASTE-DL-ALARMS'!$Q$10:$Z$2800,8,FALSE),"")
C23: =IF(D23="Critical",MAX($C$8:C22)+1,"") | D23: =TRIM(CLEAN(P23)) -> - | E23: =VLOOKUP('PASTE-DOWN-DL'!F23,'SSA-CODE'!$D$4:$E$56,2,FALSE) -> NDD | F23: =TRIM(CLEAN(SUBSTITUTE(G23,CHAR(160)," "))) -> SSA NAD | G23: =MID(I23,1,SEARCH("-",I23)-1) -> SSA NAD | H23: 14 | I23: SSA NAD-10.121.16.151-Naika_1/5-10.121.16.130-Kheda_5/3 | J23: Fiber | K23: GE | L23: Eth | M23: BI-DIR | N23: 10.121.16.151_Naika_TN703B_GJ_SSA NAD_PH3\S1P5 | O23: 10.121.16.130_Kheda_TN725B_WTR_AM_PH1\S5P3 | P23: - | Q23: 11 | R23: 100 | S23: GUJ GCS ID- 039080 | T23: 200700547 | U23: Nadiad | V23: 1.0 | W23: 2025/02/19,13:53:53 | X23: 2026/04/18,11:28:02 | Z23: =TRIM(CLEAN(I23)) -> SSA NAD-10.121.16.151-Naika_1/5-10.121.16.130-Kheda_5/3 | AA23: =SEARCH("_",N23) -> 15 | AB23: =SEARCH("_TN7",N23) -> 21 | AC23: =SEARCH("_",O23) -> 15 | AD23: =SEARCH("_TN7",O23) -> 21 | AE23: =TRIM(CLEAN(MID(N23,1,SEARCH("_",N23)-1))) -> 10.121.16.151 | AF23: =TRIM(CLEAN(MID(O23,1,SEARCH("_",O23)-1))) -> 10.121.16.130 | AG23: =MID(N23,AA23+1,AB23-AA23-1) -> Naika | AH23: =MID(O23,AC23+1,AD23-AC23-1) -> Kheda | AI23: =RIGHT(N23,LEN(N23)-SEARCH("\",N23)) -> S1P5 | AJ23: =RIGHT(O23,LEN(O23)-SEARCH("\",O23)) -> S5P3 | AK23: =IFERROR(VLOOKUP(Z23,'PASTE-DL-ALARMS'!$Q$10:$W$2200,7,FALSE),"") | AL23: =IFERROR(VLOOKUP(Z23,'PASTE-DL-ALARMS'!$Q$10:$W$2200,3,FALSE),"") | AM23: =CONCATENATE(AE23,"_",AG23,"_",AI23) -> 10.121.16.151_Naika_S1P5 | AN23: =CONCATENATE(AF23,"_",AH23,"_",AJ23) -> 10.121.16.130_Kheda_S5P3 | AO23: =$AL$3-AK23 -> #VALUE! | AP23: =IFERROR(VLOOKUP(Z23,'PASTE-DL-ALARMS'!$Q$10:$Z$2800,8,FALSE),"")
C24: =IF(D24="Critical",MAX($C$8:C23)+1,"") | D24: =TRIM(CLEAN(P24)) -> - | E24: =VLOOKUP('PASTE-DOWN-DL'!F24,'SSA-CODE'!$D$4:$E$56,2,FALSE) -> VDA | F24: =TRIM(CLEAN(SUBSTITUTE(G24,CHAR(160)," "))) -> SSA VDR | G24: =MID(I24,1,SEARCH("-",I24)-1) -> SSA VDR | H24: 15 | I24: SSA VDR-10.121.99.142-ONGC_3/1-10.121.19.132-Makarpura_5/1 | J24: Fiber | K24: 10GE | L24: Eth | M24: BI-DIR | N24: 10.121.99.142_ONGC_TN705B_GJ_SSA VDR_PH3\S3P1 | O24: 10.121.19.132_MAKARPURA_TN725B_GJ_SSA VDR_PH2\S5P1 | P24: - | Q24: 26 | R24: 56 | T24: Vikas | V24: 1.0 | W24: 2019/03/22,10:47:45 | X24: 2026/04/18,11:29:22 | Z24: =TRIM(CLEAN(I24)) -> SSA VDR-10.121.99.142-ONGC_3/1-10.121.19.132-Makarpura_5/1 | AA24: =SEARCH("_",N24) -> 15 | AB24: =SEARCH("_TN7",N24) -> 20 | AC24: =SEARCH("_",O24) -> 15 | AD24: =SEARCH("_TN7",O24) -> 25 | AE24: =TRIM(CLEAN(MID(N24,1,SEARCH("_",N24)-1))) -> 10.121.99.142 | AF24: =TRIM(CLEAN(MID(O24,1,SEARCH("_",O24)-1))) -> 10.121.19.132 | AG24: =MID(N24,AA24+1,AB24-AA24-1) -> ONGC | AH24: =MID(O24,AC24+1,AD24-AC24-1) -> MAKARPURA | AI24: =RIGHT(N24,LEN(N24)-SEARCH("\",N24)) -> S3P1 | AJ24: =RIGHT(O24,LEN(O24)-SEARCH("\",O24)) -> S5P1 | AK24: =IFERROR(VLOOKUP(Z24,'PASTE-DL-ALARMS'!$Q$10:$W$2200,7,FALSE),"") | AL24: =IFERROR(VLOOKUP(Z24,'PASTE-DL-ALARMS'!$Q$10:$W$2200,3,FALSE),"") | AM24: =CONCATENATE(AE24,"_",AG24,"_",AI24) -> 10.121.99.142_ONGC_S3P1 | AN24: =CONCATENATE(AF24,"_",AH24,"_",AJ24) -> 10.121.19.132_MAKARPURA_S5P1 | AO24: =$AL$3-AK24 -> #VALUE! | AP24: =IFERROR(VLOOKUP(Z24,'PASTE-DL-ALARMS'!$Q$10:$Z$2800,8,FALSE),"")
C25: =IF(D25="Critical",MAX($C$8:C24)+1,"") | D25: =TRIM(CLEAN(P25)) -> - | E25: =VLOOKUP('PASTE-DOWN-DL'!F25,'SSA-CODE'!$D$4:$E$56,2,FALSE) -> WTR RJ | F25: =TRIM(CLEAN(SUBSTITUTE(G25,CHAR(160)," "))) -> WTR RJ | G25: =MID(I25,1,SEARCH("-",I25)-1) -> WTR RJ | H25: 16 | I25: WTR RJ-10.121.17.129-Bhavnagar(GNE)_6/1-10.121.17.161-Bhavnagar3_6/1 | J25: Fiber | K25: 10GE | L25: Eth | M25: BI-DIR | N25: 10.121.17.161_BHAVNAGAR3_TN725B_WTR_RJ_PH2\S6P1 | O25: 10.121.17.129_BHAVNAGAR(GNE)_TN725B_WTR_RJ_PH2\S6P1 | P25: - | Q25: 84 | R25: 100 | T25: Nikhil | V25: 1.0 | W25: 2019/05/15,12:15:49 | X25: 2026/04/18,11:31:04 | Z25: =TRIM(CLEAN(I25)) -> WTR RJ-10.121.17.129-Bhavnagar(GNE)_6/1-10.121.17.161-Bhavnagar3_6/1 | AA25: =SEARCH("_",N25) -> 15 | AB25: =SEARCH("_TN7",N25) -> 26 | AC25: =SEARCH("_",O25) -> 15 | AD25: =SEARCH("_TN7",O25) -> 30 | AE25: =TRIM(CLEAN(MID(N25,1,SEARCH("_",N25)-1))) -> 10.121.17.161 | AF25: =TRIM(CLEAN(MID(O25,1,SEARCH("_",O25)-1))) -> 10.121.17.129 | AG25: =MID(N25,AA25+1,AB25-AA25-1) -> BHAVNAGAR3 | AH25: =MID(O25,AC25+1,AD25-AC25-1) -> BHAVNAGAR(GNE) | AI25: =RIGHT(N25,LEN(N25)-SEARCH("\",N25)) -> S6P1 | AJ25: =RIGHT(O25,LEN(O25)-SEARCH("\",O25)) -> S6P1 | AK25: =IFERROR(VLOOKUP(Z25,'PASTE-DL-ALARMS'!$Q$10:$W$2200,7,FALSE),"") | AL25: =IFERROR(VLOOKUP(Z25,'PASTE-DL-ALARMS'!$Q$10:$W$2200,3,FALSE),"") | AM25: =CONCATENATE(AE25,"_",AG25,"_",AI25) -> 10.121.17.161_BHAVNAGAR3_S6P1 | AN25: =CONCATENATE(AF25,"_",AH25,"_",AJ25) -> 10.121.17.129_BHAVNAGAR(GNE)_S6P1 | AO25: =$AL$3-AK25 -> #VALUE! | AP25: =IFERROR(VLOOKUP(Z25,'PASTE-DL-ALARMS'!$Q$10:$Z$2800,8,FALSE),"")
C26: =IF(D26="Critical",MAX($C$8:C25)+1,"") | D26: =TRIM(CLEAN(P26)) -> - | E26: =VLOOKUP('PASTE-DOWN-DL'!F26,'SSA-CODE'!$D$4:$E$56,2,FALSE) -> AHD | F26: =TRIM(CLEAN(SUBSTITUTE(G26,CHAR(160)," "))) -> SSA AM | G26: =MID(I26,1,SEARCH("-",I26)-1) -> SSA AM | H26: 17 | I26: SSA AM-10.121.18.243-Bhat_4/5-10.121.18.239-IPR Bhat_2/5 | J26: Fiber | K26: GE | L26: Eth | M26: BI-DIR | N26: 10.121.18.243_Bhat_TN705B_GJ_SSA AM_PH2\S4P5 | O26: 10.121.18.239_IPR Bhat_TN703B_GJ_SSA AM_PH2\S2P5 | P26: - | Q26: 6 | R26: 98 | S26: Ahmedabad SSA-0007842 | T26: ritesh | V26: 1.0 | W26: 2020/09/16,20:02:14 | X26: 2026/04/18,11:31:31 | Z26: =TRIM(CLEAN(I26)) -> SSA AM-10.121.18.243-Bhat_4/5-10.121.18.239-IPR Bhat_2/5 | AA26: =SEARCH("_",N26) -> 15 | AB26: =SEARCH("_TN7",N26) -> 20 | AC26: =SEARCH("_",O26) -> 15 | AD26: =SEARCH("_TN7",O26) -> 24 | AE26: =TRIM(CLEAN(MID(N26,1,SEARCH("_",N26)-1))) -> 10.121.18.243 | AF26: =TRIM(CLEAN(MID(O26,1,SEARCH("_",O26)-1))) -> 10.121.18.239 | AG26: =MID(N26,AA26+1,AB26-AA26-1) -> Bhat | AH26: =MID(O26,AC26+1,AD26-AC26-1) -> IPR Bhat | AI26: =RIGHT(N26,LEN(N26)-SEARCH("\",N26)) -> S4P5 | AJ26: =RIGHT(O26,LEN(O26)-SEARCH("\",O26)) -> S2P5 | AK26: =IFERROR(VLOOKUP(Z26,'PASTE-DL-ALARMS'!$Q$10:$W$2200,7,FALSE),"") | AL26: =IFERROR(VLOOKUP(Z26,'PASTE-DL-ALARMS'!$Q$10:$W$2200,3,FALSE),"") | AM26: =CONCATENATE(AE26,"_",AG26,"_",AI26) -> 10.121.18.243_Bhat_S4P5 | AN26: =CONCATENATE(AF26,"_",AH26,"_",AJ26) -> 10.121.18.239_IPR Bhat_S2P5 | AO26: =$AL$3-AK26 -> #VALUE! | AP26: =IFERROR(VLOOKUP(Z26,'PASTE-DL-ALARMS'!$Q$10:$Z$2800,8,FALSE),"")
C27: =IF(D27="Critical",MAX($C$8:C26)+1,"") | D27: =TRIM(CLEAN(P27)) -> - | E27: =VLOOKUP('PASTE-DOWN-DL'!F27,'SSA-CODE'!$D$4:$E$56,2,FALSE) -> JND | F27: =TRIM(CLEAN(SUBSTITUTE(G27,CHAR(160)," "))) -> SSA JND | G27: =MID(I27,1,SEARCH("-",I27)-1) -> SSA JND | H27: 18 | I27: SSA JND-10.121.24.7-Veraval_TE_5/1-10.121.97.230-Ajotha_TE_4/1 | J27: Fiber | K27: 10GE | L27: Eth | M27: BI-DIR | N27: 10.121.24.7_VERAVALTE B1_TN725B_GJ_SSA JND_PH2\S5P1 | O27: 10.121.97.230_AJOTHA TE_TN705B_GJ_SSA JND_PH3\S4P1 | P27: - | Q27: 2 | R27: 11 | S27: Guj GCS ID No.- 048227 | T27: 200700547 | U27: SSA JND | V27: 1.0 | W27: 2026/01/20,13:04:30 | X27: 2026/04/18,11:32:13 | Z27: =TRIM(CLEAN(I27)) -> SSA JND-10.121.24.7-Veraval_TE_5/1-10.121.97.230-Ajotha_TE_4/1 | AA27: =SEARCH("_",N27) -> 13 | AB27: =SEARCH("_TN7",N27) -> 26 | AC27: =SEARCH("_",O27) -> 15 | AD27: =SEARCH("_TN7",O27) -> 25 | AE27: =TRIM(CLEAN(MID(N27,1,SEARCH("_",N27)-1))) -> 10.121.24.7 | AF27: =TRIM(CLEAN(MID(O27,1,SEARCH("_",O27)-1))) -> 10.121.97.230 | AG27: =MID(N27,AA27+1,AB27-AA27-1) -> VERAVALTE B1 | AH27: =MID(O27,AC27+1,AD27-AC27-1) -> AJOTHA TE | AI27: =RIGHT(N27,LEN(N27)-SEARCH("\",N27)) -> S5P1 | AJ27: =RIGHT(O27,LEN(O27)-SEARCH("\",O27)) -> S4P1 | AK27: =IFERROR(VLOOKUP(Z27,'PASTE-DL-ALARMS'!$Q$10:$W$2200,7,FALSE),"") | AL27: =IFERROR(VLOOKUP(Z27,'PASTE-DL-ALARMS'!$Q$10:$W$2200,3,FALSE),"") | AM27: =CONCATENATE(AE27,"_",AG27,"_",AI27) -> 10.121.24.7_VERAVALTE B1_S5P1 | AN27: =CONCATENATE(AF27,"_",AH27,"_",AJ27) -> 10.121.97.230_AJOTHA TE_S4P1 | AO27: =$AL$3-AK27 -> #VALUE! | AP27: =IFERROR(VLOOKUP(Z27,'PASTE-DL-ALARMS'!$Q$10:$Z$2800,8,FALSE),"")
C28: =IF(D28="Critical",MAX($C$8:C27)+1,"") | D28: =TRIM(CLEAN(P28)) -> - | E28: =VLOOKUP('PASTE-DOWN-DL'!F28,'SSA-CODE'!$D$4:$E$56,2,FALSE) -> VDA | F28: =TRIM(CLEAN(SUBSTITUTE(G28,CHAR(160)," "))) -> SSA VDR | G28: =MID(I28,1,SEARCH("-",I28)-1) -> SSA VDR | H28: 19 | I28: SSA VDR-10.121.19.142-Gotri_Medical_1/5-10.121.19.136-Gotri_3/2 | J28: Fiber | K28: GE | L28: Eth | M28: BI-DIR | N28: 10.121.19.142_GOTRI Medical_TN703B_GJ_SSA VDR_PH3\S1P5 | O28: 10.121.19.136_GOTRI_TN705B_GJ_SSA VDR_PH2\S3P2 | P28: - | Q28: 25 | R28: 100 | S28: Vadodara SSA | T28: minaxikataria | U28: Vadodara SSA | V28: 1.0 | W28: 2022/02/07,12:58:48 | X28: 2026/04/20,13:02:16 | Z28: =TRIM(CLEAN(I28)) -> SSA VDR-10.121.19.142-Gotri_Medical_1/5-10.121.19.136-Gotri_3/2 | AA28: =SEARCH("_",N28) -> 15 | AB28: =SEARCH("_TN7",N28) -> 29 | AC28: =SEARCH("_",O28) -> 15 | AD28: =SEARCH("_TN7",O28) -> 21 | AE28: =TRIM(CLEAN(MID(N28,1,SEARCH("_",N28)-1))) -> 10.121.19.142 | AF28: =TRIM(CLEAN(MID(O28,1,SEARCH("_",O28)-1))) -> 10.121.19.136 | AG28: =MID(N28,AA28+1,AB28-AA28-1) -> GOTRI Medical | AH28: =MID(O28,AC28+1,AD28-AC28-1) -> GOTRI | AI28: =RIGHT(N28,LEN(N28)-SEARCH("\",N28)) -> S1P5 | AJ28: =RIGHT(O28,LEN(O28)-SEARCH("\",O28)) -> S3P2 | AK28: =IFERROR(VLOOKUP(Z28,'PASTE-DL-ALARMS'!$Q$10:$W$2200,7,FALSE),"") | AL28: =IFERROR(VLOOKUP(Z28,'PASTE-DL-ALARMS'!$Q$10:$W$2200,3,FALSE),"") | AM28: =CONCATENATE(AE28,"_",AG28,"_",AI28) -> 10.121.19.142_GOTRI Medical_S1P5 | AN28: =CONCATENATE(AF28,"_",AH28,"_",AJ28) -> 10.121.19.136_GOTRI_S3P2 | AO28: =$AL$3-AK28 -> #VALUE! | AP28: =IFERROR(VLOOKUP(Z28,'PASTE-DL-ALARMS'!$Q$10:$Z$2800,8,FALSE),"")
C29: =IF(D29="Critical",MAX($C$8:C28)+1,"") | D29: =TRIM(CLEAN(P29)) -> - | E29: =VLOOKUP('PASTE-DOWN-DL'!F29,'SSA-CODE'!$D$4:$E$56,2,FALSE) -> MSN | F29: =TRIM(CLEAN(SUBSTITUTE(G29,CHAR(160)," "))) -> SSA MEH | G29: =MID(I29,1,SEARCH("-",I29)-1) -> SSA MEH | H29: 20 | I29: SSA MEH-10.121.25.102-Sipor_Exch_2/5-10.121.25.80-Shapar_Exch_1/5 | J29: Fiber | K29: GE | L29: Eth | M29: BI-DIR | N29: 10.121.25.102_SIPOR EXCH_TN703B_GJ_SSA MEH_PH2\S2P5 | O29: 10.121.25.80_SHAPUR EXCH_TN703B_GJ_SSA MEH_PH2\S1P5 | P29: - | Q29: 9 | R29: 100 | S29: GCS-46197 | T29: 200800474 | U29: GCS-46197 | V29: 1.0 | W29: 2025/11/04,22:04:31 | X29: 2026/04/18,11:33:17 | Z29: =TRIM(CLEAN(I29)) -> SSA MEH-10.121.25.102-Sipor_Exch_2/5-10.121.25.80-Shapar_Exch_1/5 | AA29: =SEARCH("_",N29) -> 15 | AB29: =SEARCH("_TN7",N29) -> 26 | AC29: =SEARCH("_",O29) -> 14 | AD29: =SEARCH("_TN7",O29) -> 26 | AE29: =TRIM(CLEAN(MID(N29,1,SEARCH("_",N29)-1))) -> 10.121.25.102 | AF29: =TRIM(CLEAN(MID(O29,1,SEARCH("_",O29)-1))) -> 10.121.25.80 | AG29: =MID(N29,AA29+1,AB29-AA29-1) -> SIPOR EXCH | AH29: =MID(O29,AC29+1,AD29-AC29-1) -> SHAPUR EXCH | AI29: =RIGHT(N29,LEN(N29)-SEARCH("\",N29)) -> S2P5 | AJ29: =RIGHT(O29,LEN(O29)-SEARCH("\",O29)) -> S1P5 | AK29: =IFERROR(VLOOKUP(Z29,'PASTE-DL-ALARMS'!$Q$10:$W$2200,7,FALSE),"") | AL29: =IFERROR(VLOOKUP(Z29,'PASTE-DL-ALARMS'!$Q$10:$W$2200,3,FALSE),"") | AM29: =CONCATENATE(AE29,"_",AG29,"_",AI29) -> 10.121.25.102_SIPOR EXCH_S2P5 | AN29: =CONCATENATE(AF29,"_",AH29,"_",AJ29) -> 10.121.25.80_SHAPUR EXCH_S1P5 | AO29: =$AL$3-AK29 -> #VALUE! | AP29: =IFERROR(VLOOKUP(Z29,'PASTE-DL-ALARMS'!$Q$10:$Z$2800,8,FALSE),"")
C30: =IF(D30="Critical",MAX($C$8:C29)+1,"") | D30: =TRIM(CLEAN(P30)) -> - | E30: =VLOOKUP('PASTE-DOWN-DL'!F30,'SSA-CODE'!$D$4:$E$56,2,FALSE) -> BUJ | F30: =TRIM(CLEAN(SUBSTITUTE(G30,CHAR(160)," "))) -> SSA BUJ | G30: =MID(I30,1,SEARCH("-",I30)-1) -> SSA BUJ | H30: 21 | I30: SSA BUJ-10.121.17.86-Kunvarbet_Army_1/5-10.121.96.187-Khavda_5/5 | J30: Fiber | K30: GE | L30: Eth | M30: BI-DIR | N30: 10.121.17.86_Kunvarbet Army_TN703B_GJ_SSA BUJ_PH3\S1P5 | O30: 10.121.96.187_KHAVDA_TN725B_GJ_SSA BUJ_PH3\S5P5 | P30: - | Q30: 5 | R30: 96 | S30: Bhuj SSA GCS ID 43615 | T30: 200800716 | U30: Bhuj SSA GCS ID 43615 | V30: 1.0 | W30: 2025/07/29,14:54:33 | X30: 2026/04/18,11:33:39 | Z30: =TRIM(CLEAN(I30)) -> SSA BUJ-10.121.17.86-Kunvarbet_Army_1/5-10.121.96.187-Khavda_5/5 | AA30: =SEARCH("_",N30) -> 14 | AB30: =SEARCH("_TN7",N30) -> 29 | AC30: =SEARCH("_",O30) -> 15 | AD30: =SEARCH("_TN7",O30) -> 22 | AE30: =TRIM(CLEAN(MID(N30,1,SEARCH("_",N30)-1))) -> 10.121.17.86 | AF30: =TRIM(CLEAN(MID(O30,1,SEARCH("_",O30)-1))) -> 10.121.96.187 | AG30: =MID(N30,AA30+1,AB30-AA30-1) -> Kunvarbet Army | AH30: =MID(O30,AC30+1,AD30-AC30-1) -> KHAVDA | AI30: =RIGHT(N30,LEN(N30)-SEARCH("\",N30)) -> S1P5 | AJ30: =RIGHT(O30,LEN(O30)-SEARCH("\",O30)) -> S5P5 | AK30: =IFERROR(VLOOKUP(Z30,'PASTE-DL-ALARMS'!$Q$10:$W$2200,7,FALSE),"") | AL30: =IFERROR(VLOOKUP(Z30,'PASTE-DL-ALARMS'!$Q$10:$W$2200,3,FALSE),"") | AM30: =CONCATENATE(AE30,"_",AG30,"_",AI30) -> 10.121.17.86_Kunvarbet Army_S1P5 | AN30: =CONCATENATE(AF30,"_",AH30,"_",AJ30) -> 10.121.96.187_KHAVDA_S5P5 | AO30: =$AL$3-AK30 -> #VALUE! | AP30: =IFERROR(VLOOKUP(Z30,'PASTE-DL-ALARMS'!$Q$10:$Z$2800,8,FALSE),"")
C31: =IF(D31="Critical",MAX($C$8:C30)+1,"") | D31: =TRIM(CLEAN(P31)) -> - | E31: =VLOOKUP('PASTE-DOWN-DL'!F31,'SSA-CODE'!$D$4:$E$56,2,FALSE) -> VAL | F31: =TRIM(CLEAN(SUBSTITUTE(G31,CHAR(160)," "))) -> SSA VAL | G31: =MID(I31,1,SEARCH("-",I31)-1) -> SSA VAL | H31: 22 | I31: SSA VAL-10.121.16.67-Navasari_4/2-10.121.16.121-Navsari Agricultural University_2/5 | J31: Fiber | K31: GE | L31: Eth | M31: BI-DIR | N31: 10.121.16.67_NAVASARI_TN725B_WTR_AM_PH2\S4P2 | O31: 10.121.16.121_Navsari Agricultural University_TN703B_GJ_SSA VAL_PH2\S2P5 | P31: - | Q31: 8 | R31: 99 | S31: Valsad SSA GCS ID 19649 | T31: 200800716 | U31: Valsad SSA GCS ID 19649 | V31: 1.0 | W31: 2022/10/30,00:07:57 | X31: 2026/04/18,11:38:21 | Z31: =TRIM(CLEAN(I31)) -> SSA VAL-10.121.16.67-Navasari_4/2-10.121.16.121-Navsari Agricultural University_2/5 | AA31: =SEARCH("_",N31) -> 14 | AB31: =SEARCH("_TN7",N31) -> 23 | AC31: =SEARCH("_",O31) -> 15 | AD31: =SEARCH("_TN7",O31) -> 47 | AE31: =TRIM(CLEAN(MID(N31,1,SEARCH("_",N31)-1))) -> 10.121.16.67 | AF31: =TRIM(CLEAN(MID(O31,1,SEARCH("_",O31)-1))) -> 10.121.16.121 | AG31: =MID(N31,AA31+1,AB31-AA31-1) -> NAVASARI | AH31: =MID(O31,AC31+1,AD31-AC31-1) -> Navsari Agricultural University | AI31: =RIGHT(N31,LEN(N31)-SEARCH("\",N31)) -> S4P2 | AJ31: =RIGHT(O31,LEN(O31)-SEARCH("\",O31)) -> S2P5 | AK31: =IFERROR(VLOOKUP(Z31,'PASTE-DL-ALARMS'!$Q$10:$W$2200,7,FALSE),"") | AL31: =IFERROR(VLOOKUP(Z31,'PASTE-DL-ALARMS'!$Q$10:$W$2200,3,FALSE),"") | AM31: =CONCATENATE(AE31,"_",AG31,"_",AI31) -> 10.121.16.67_NAVASARI_S4P2 | AN31: =CONCATENATE(AF31,"_",AH31,"_",AJ31) -> 10.121.16.121_Navsari Agricultural University_S2P5 | AO31: =$AL$3-AK31 -> #VALUE! | AP31: =IFERROR(VLOOKUP(Z31,'PASTE-DL-ALARMS'!$Q$10:$Z$2800,8,FALSE),"")
C32: =IF(D32="Critical",MAX($C$8:C31)+1,"") | D32: =TRIM(CLEAN(P32)) -> - | E32: =VLOOKUP('PASTE-DOWN-DL'!F32,'SSA-CODE'!$D$4:$E$56,2,FALSE) -> NDD | F32: =TRIM(CLEAN(SUBSTITUTE(G32,CHAR(160)," "))) -> SSA NAD | G32: =MID(I32,1,SEARCH("-",I32)-1) -> SSA NAD | H32: 23 | I32: SSA NAD-10.121.24.238-Sojitra_4/2-10.121.98.85-Vatav _1/5 | J32: Fiber | K32: GE | L32: Eth | M32: BI-DIR | N32: 10.121.24.238_Sojitra B1_TN705B_GJ_SSA NAD_PH2\S4P2 | O32: 10.121.98.85_Vatav _TN703B_GJ_SSA NAD_PH3\S1P5 | P32: - | Q32: 48 | R32: 100 | S32: Nadiad SSA GCS ID 45911 | T32: 200800716 | U32: Nadiad SSA GCS ID 45911 | V32: 1.0 | W32: 2025/10/16,00:13:18 | X32: 2026/04/18,11:38:49 | Z32: =TRIM(CLEAN(I32)) -> SSA NAD-10.121.24.238-Sojitra_4/2-10.121.98.85-Vatav _1/5 | AA32: =SEARCH("_",N32) -> 15 | AB32: =SEARCH("_TN7",N32) -> 26 | AC32: =SEARCH("_",O32) -> 14 | AD32: =SEARCH("_TN7",O32) -> 21 | AE32: =TRIM(CLEAN(MID(N32,1,SEARCH("_",N32)-1))) -> 10.121.24.238 | AF32: =TRIM(CLEAN(MID(O32,1,SEARCH("_",O32)-1))) -> 10.121.98.85 | AG32: =MID(N32,AA32+1,AB32-AA32-1) -> Sojitra B1 | AH32: =MID(O32,AC32+1,AD32-AC32-1) -> Vatav | AI32: =RIGHT(N32,LEN(N32)-SEARCH("\",N32)) -> S4P2 | AJ32: =RIGHT(O32,LEN(O32)-SEARCH("\",O32)) -> S1P5 | AK32: =IFERROR(VLOOKUP(Z32,'PASTE-DL-ALARMS'!$Q$10:$W$2200,7,FALSE),"") | AL32: =IFERROR(VLOOKUP(Z32,'PASTE-DL-ALARMS'!$Q$10:$W$2200,3,FALSE),"") | AM32: =CONCATENATE(AE32,"_",AG32,"_",AI32) -> 10.121.24.238_Sojitra B1_S4P2 | AN32: =CONCATENATE(AF32,"_",AH32,"_",AJ32) -> 10.121.98.85_Vatav _S1P5 | AO32: =$AL$3-AK32 -> #VALUE! | AP32: =IFERROR(VLOOKUP(Z32,'PASTE-DL-ALARMS'!$Q$10:$Z$2800,8,FALSE),"")
C33: =IF(D33="Critical",MAX($C$8:C32)+1,"") | D33: =TRIM(CLEAN(P33)) -> - | E33: =VLOOKUP('PASTE-DOWN-DL'!F33,'SSA-CODE'!$D$4:$E$56,2,FALSE) -> WTR AM | F33: =TRIM(CLEAN(SUBSTITUTE(G33,CHAR(160)," "))) -> WTR AM | G33: =MID(I33,1,SEARCH("-",I33)-1) -> WTR AM | H33: 24 | I33: WTR AM-10.121.15.132-Gandhinagar_6/1-10.121.15.193-Mehsana3(GNE)_6/1 | J33: Fiber | K33: 10GE | L33: Eth | M33: BI-DIR | N33: 10.121.15.132_GANDHINAGAR_TN725B_WTR_AM_PH1\S6P1 | O33: 10.121.15.193_Mehsana3(GNE)_TN725B_WTR_AM_PH1\S6P1 | P33: - | Q33: 16 | R33: 25 | T33: Jayesh | V33: 1.0 | W33: 2023/02/09,14:48:21 | X33: 2026/04/18,11:39:31 | Z33: =TRIM(CLEAN(I33)) -> WTR AM-10.121.15.132-Gandhinagar_6/1-10.121.15.193-Mehsana3(GNE)_6/1 | AA33: =SEARCH("_",N33) -> 15 | AB33: =SEARCH("_TN7",N33) -> 27 | AC33: =SEARCH("_",O33) -> 15 | AD33: =SEARCH("_TN7",O33) -> 29 | AE33: =TRIM(CLEAN(MID(N33,1,SEARCH("_",N33)-1))) -> 10.121.15.132 | AF33: =TRIM(CLEAN(MID(O33,1,SEARCH("_",O33)-1))) -> 10.121.15.193 | AG33: =MID(N33,AA33+1,AB33-AA33-1) -> GANDHINAGAR | AH33: =MID(O33,AC33+1,AD33-AC33-1) -> Mehsana3(GNE) | AI33: =RIGHT(N33,LEN(N33)-SEARCH("\",N33)) -> S6P1 | AJ33: =RIGHT(O33,LEN(O33)-SEARCH("\",O33)) -> S6P1 | AK33: =IFERROR(VLOOKUP(Z33,'PASTE-DL-ALARMS'!$Q$10:$W$2200,7,FALSE),"") | AL33: =IFERROR(VLOOKUP(Z33,'PASTE-DL-ALARMS'!$Q$10:$W$2200,3,FALSE),"") | AM33: =CONCATENATE(AE33,"_",AG33,"_",AI33) -> 10.121.15.132_GANDHINAGAR_S6P1 | AN33: =CONCATENATE(AF33,"_",AH33,"_",AJ33) -> 10.121.15.193_Mehsana3(GNE)_S6P1 | AO33: =$AL$3-AK33 -> #VALUE! | AP33: =IFERROR(VLOOKUP(Z33,'PASTE-DL-ALARMS'!$Q$10:$Z$2800,8,FALSE),"")
C34: =IF(D34="Critical",MAX($C$8:C33)+1,"") | D34: =TRIM(CLEAN(P34)) -> - | E34: =VLOOKUP('PASTE-DOWN-DL'!F34,'SSA-CODE'!$D$4:$E$56,2,FALSE) -> SEN | F34: =TRIM(CLEAN(SUBSTITUTE(G34,CHAR(160)," "))) -> SSA SEN | G34: =MID(I34,1,SEARCH("-",I34)-1) -> SSA SEN | H34: 25 | I34: SSA SEN-10.121.99.5-Dhangdhra_4/1-10.121.69.74-Khambhada_3/1 | J34: Fiber | K34: 10GE | L34: Eth | M34: BI-DIR | N34: 10.121.99.5_DHANGDHRA_TN725B_GJ_SSA SEN_PH3\S4P1 | O34: 10.121.69.74_Khambhada_TN705B_WTR_RJ_PH1\S3P1 | P34: - | Q34: 23 | R34: 32 | T34: Rahul | V34: 1.0 | W34: 2020/11/20,16:57:32 | X34: 2026/04/18,11:40:15 | Z34: =TRIM(CLEAN(I34)) -> SSA SEN-10.121.99.5-Dhangdhra_4/1-10.121.69.74-Khambhada_3/1 | AA34: =SEARCH("_",N34) -> 13 | AB34: =SEARCH("_TN7",N34) -> 23 | AC34: =SEARCH("_",O34) -> 14 | AD34: =SEARCH("_TN7",O34) -> 24 | AE34: =TRIM(CLEAN(MID(N34,1,SEARCH("_",N34)-1))) -> 10.121.99.5 | AF34: =TRIM(CLEAN(MID(O34,1,SEARCH("_",O34)-1))) -> 10.121.69.74 | AG34: =MID(N34,AA34+1,AB34-AA34-1) -> DHANGDHRA | AH34: =MID(O34,AC34+1,AD34-AC34-1) -> Khambhada | AI34: =RIGHT(N34,LEN(N34)-SEARCH("\",N34)) -> S4P1 | AJ34: =RIGHT(O34,LEN(O34)-SEARCH("\",O34)) -> S3P1 | AK34: =IFERROR(VLOOKUP(Z34,'PASTE-DL-ALARMS'!$Q$10:$W$2200,7,FALSE),"") | AL34: =IFERROR(VLOOKUP(Z34,'PASTE-DL-ALARMS'!$Q$10:$W$2200,3,FALSE),"") | AM34: =CONCATENATE(AE34,"_",AG34,"_",AI34) -> 10.121.99.5_DHANGDHRA_S4P1 | AN34: =CONCATENATE(AF34,"_",AH34,"_",AJ34) -> 10.121.69.74_Khambhada_S3P1 | AO34: =$AL$3-AK34 -> #VALUE! | AP34: =IFERROR(VLOOKUP(Z34,'PASTE-DL-ALARMS'!$Q$10:$Z$2800,8,FALSE),"")
C35: =IF(D35="Critical",MAX($C$8:C34)+1,"") | D35: =TRIM(CLEAN(P35)) -> - | E35: =VLOOKUP('PASTE-DOWN-DL'!F35,'SSA-CODE'!$D$4:$E$56,2,FALSE) -> VDA | F35: =TRIM(CLEAN(SUBSTITUTE(G35,CHAR(160)," "))) -> SSA VDR | G35: =MID(I35,1,SEARCH("-",I35)-1) -> SSA VDR | H35: 26 | I35: SSA VDR-10.121.19.138-City2_5/8-10.121.99.150-City3_5/8 | J35: Twisted-Pair | K35: GE | L35: Eth | M35: BI-DIR | N35: 10.121.19.138_CITY2_TN725B_GJ_SSA VDR_PH2\S5P8 | O35: 10.121.99.150_CITY 3_TN725B_GJ_SSA VDR_PH3\S5P8 | P35: - | Q35: 97 | R35: 100 | S35: GUJ_GCS_ID_0018854 | T35: 200800788 | U35: VADODARA_SSA | V35: 1.0 | W35: 2022/09/21,15:43:13 | X35: 2026/04/18,11:40:42 | Z35: =TRIM(CLEAN(I35)) -> SSA VDR-10.121.19.138-City2_5/8-10.121.99.150-City3_5/8 | AA35: =SEARCH("_",N35) -> 15 | AB35: =SEARCH("_TN7",N35) -> 21 | AC35: =SEARCH("_",O35) -> 15 | AD35: =SEARCH("_TN7",O35) -> 22 | AE35: =TRIM(CLEAN(MID(N35,1,SEARCH("_",N35)-1))) -> 10.121.19.138 | AF35: =TRIM(CLEAN(MID(O35,1,SEARCH("_",O35)-1))) -> 10.121.99.150 | AG35: =MID(N35,AA35+1,AB35-AA35-1) -> CITY2 | AH35: =MID(O35,AC35+1,AD35-AC35-1) -> CITY 3 | AI35: =RIGHT(N35,LEN(N35)-SEARCH("\",N35)) -> S5P8 | AJ35: =RIGHT(O35,LEN(O35)-SEARCH("\",O35)) -> S5P8 | AK35: =IFERROR(VLOOKUP(Z35,'PASTE-DL-ALARMS'!$Q$10:$W$2200,7,FALSE),"") | AL35: =IFERROR(VLOOKUP(Z35,'PASTE-DL-ALARMS'!$Q$10:$W$2200,3,FALSE),"") | AM35: =CONCATENATE(AE35,"_",AG35,"_",AI35) -> 10.121.19.138_CITY2_S5P8 | AN35: =CONCATENATE(AF35,"_",AH35,"_",AJ35) -> 10.121.99.150_CITY 3_S5P8 | AO35: =$AL$3-AK35 -> #VALUE! | AP35: =IFERROR(VLOOKUP(Z35,'PASTE-DL-ALARMS'!$Q$10:$Z$2800,8,FALSE),"")
C36: =IF(D36="Critical",MAX($C$8:C35)+1,"") | D36: =TRIM(CLEAN(P36)) -> - | E36: =VLOOKUP('PASTE-DOWN-DL'!F36,'SSA-CODE'!$D$4:$E$56,2,FALSE) -> HMR | F36: =TRIM(CLEAN(SUBSTITUTE(G36,CHAR(160)," "))) -> SSA HMR | G36: =MID(I36,1,SEARCH("-",I36)-1) -> SSA HMR | H36: 27 | I36: SSA HMR-10.121.97.80-Raigad_1/5-10.121.25.165-Gambhoi_4/4 | J36: Fiber | K36: GE | L36: Eth | M36: BI-DIR | N36: 10.121.97.80_RAIGAD_TN703B_GJ_SSA HMR_PH3\S1P5 | O36: 10.121.25.165_GAMBHOI_TN705B_GJ_SSA HMR_PH2\S4P4 | P36: - | Q36: 25 | R36: 100 | S36: HMR SSA GCS ID 7684 | T36: 200800716 | U36: HMR SSA | V36: 1.0 | W36: 2020/09/08,12:16:33 | X36: 2026/04/18,11:41:12 | Z36: =TRIM(CLEAN(I36)) -> SSA HMR-10.121.97.80-Raigad_1/5-10.121.25.165-Gambhoi_4/4 | AA36: =SEARCH("_",N36) -> 14 | AB36: =SEARCH("_TN7",N36) -> 21 | AC36: =SEARCH("_",O36) -> 15 | AD36: =SEARCH("_TN7",O36) -> 23 | AE36: =TRIM(CLEAN(MID(N36,1,SEARCH("_",N36)-1))) -> 10.121.97.80 | AF36: =TRIM(CLEAN(MID(O36,1,SEARCH("_",O36)-1))) -> 10.121.25.165 | AG36: =MID(N36,AA36+1,AB36-AA36-1) -> RAIGAD | AH36: =MID(O36,AC36+1,AD36-AC36-1) -> GAMBHOI | AI36: =RIGHT(N36,LEN(N36)-SEARCH("\",N36)) -> S1P5 | AJ36: =RIGHT(O36,LEN(O36)-SEARCH("\",O36)) -> S4P4 | AK36: =IFERROR(VLOOKUP(Z36,'PASTE-DL-ALARMS'!$Q$10:$W$2200,7,FALSE),"") | AL36: =IFERROR(VLOOKUP(Z36,'PASTE-DL-ALARMS'!$Q$10:$W$2200,3,FALSE),"") | AM36: =CONCATENATE(AE36,"_",AG36,"_",AI36) -> 10.121.97.80_RAIGAD_S1P5 | AN36: =CONCATENATE(AF36,"_",AH36,"_",AJ36) -> 10.121.25.165_GAMBHOI_S4P4 | AO36: =$AL$3-AK36 -> #VALUE! | AP36: =IFERROR(VLOOKUP(Z36,'PASTE-DL-ALARMS'!$Q$10:$Z$2800,8,FALSE),"")
C37: =IF(D37="Critical",MAX($C$8:C36)+1,"") -> 1 | D37: =TRIM(CLEAN(P37)) -> Critical | E37: =VLOOKUP('PASTE-DOWN-DL'!F37,'SSA-CODE'!$D$4:$E$56,2,FALSE) -> VAL | F37: =TRIM(CLEAN(SUBSTITUTE(G37,CHAR(160)," "))) -> SSA VAL | G37: =MID(I37,1,SEARCH("-",I37)-1) -> SSA VAL | H37: 28 | I37: SSA VAL-10.121.16.107-KAPRADA_4/3-10.121.24.167-DAPADA_4/2 | J37: Fiber | K37: GE | L37: Eth | M37: BI-DIR | N37: 10.121.16.107_KAPRADA-TE_TN725B_GJ_SSA VAL_PH3\S4P3 | O37: 10.121.24.167_DAPADA_TN705B_GJ_SSA VAL_PH3\S4P2 | P37: Critical | Q37: 18 | R37: 100 | S37: GUJ_VAL_GCSID_61002 | T37: 200300828 | U37: VALSAD SSA | V37: 1.0 | W37: 2026/05/05,18:11:37 | X37: 2026/05/12,17:50:13 | Z37: =TRIM(CLEAN(I37)) -> SSA VAL-10.121.16.107-KAPRADA_4/3-10.121.24.167-DAPADA_4/2 | AA37: =SEARCH("_",N37) -> 15 | AB37: =SEARCH("_TN7",N37) -> 26 | AC37: =SEARCH("_",O37) -> 15 | AD37: =SEARCH("_TN7",O37) -> 22 | AE37: =TRIM(CLEAN(MID(N37,1,SEARCH("_",N37)-1))) -> 10.121.16.107 | AF37: =TRIM(CLEAN(MID(O37,1,SEARCH("_",O37)-1))) -> 10.121.24.167 | AG37: =MID(N37,AA37+1,AB37-AA37-1) -> KAPRADA-TE | AH37: =MID(O37,AC37+1,AD37-AC37-1) -> DAPADA | AI37: =RIGHT(N37,LEN(N37)-SEARCH("\",N37)) -> S4P3 | AJ37: =RIGHT(O37,LEN(O37)-SEARCH("\",O37)) -> S4P2 | AK37: =IFERROR(VLOOKUP(Z37,'PASTE-DL-ALARMS'!$Q$10:$W$2200,7,FALSE),"") -> 15-05-2026 | AL37: =IFERROR(VLOOKUP(Z37,'PASTE-DL-ALARMS'!$Q$10:$W$2200,3,FALSE),"") -> 16:22:47 | AM37: =CONCATENATE(AE37,"_",AG37,"_",AI37) -> 10.121.16.107_KAPRADA-TE_S4P3 | AN37: =CONCATENATE(AF37,"_",AH37,"_",AJ37) -> 10.121.24.167_DAPADA_S4P2 | AO37: =$AL$3-AK37 -> 0 | AP37: =IFERROR(VLOOKUP(Z37,'PASTE-DL-ALARMS'!$Q$10:$Z$2800,8,FALSE),"") -> 2026/05/15,16:22:47
C38: =IF(D38="Critical",MAX($C$8:C37)+1,"") | D38: =TRIM(CLEAN(P38)) -> - | E38: =VLOOKUP('PASTE-DOWN-DL'!F38,'SSA-CODE'!$D$4:$E$56,2,FALSE) -> VDA | F38: =TRIM(CLEAN(SUBSTITUTE(G38,CHAR(160)," "))) -> SSA VDR | G38: =MID(I38,1,SEARCH("-",I38)-1) -> SSA VDR | H38: 29 | I38: SSA VDR-10.121.19.132-Makarpura_4/6-10.121.99.158-MGVCL_Tarsli_1/6 | J38: Fiber | K38: GE | L38: Eth | M38: BI-DIR | N38: 10.121.19.132_MAKARPURA_TN725B_GJ_SSA VDR_PH2\S4P6 | O38: 10.121.99.158_MGVCL TARSLI_TN703B_GJ_SSA VDR_PH3\S1P6 | P38: - | Q38: 6 | R38: 97 | S38: Vadodara SSA GCS ID14252 | T38: 200800716 | U38: Vadodara SSA GCS ID14252 | V38: 1.0 | W38: 2022/01/13,19:35:14 | X38: 2026/04/18,11:46:22 | Z38: =TRIM(CLEAN(I38)) -> SSA VDR-10.121.19.132-Makarpura_4/6-10.121.99.158-MGVCL_Tarsli_1/6 | AA38: =SEARCH("_",N38) -> 15 | AB38: =SEARCH("_TN7",N38) -> 25 | AC38: =SEARCH("_",O38) -> 15 | AD38: =SEARCH("_TN7",O38) -> 28 | AE38: =TRIM(CLEAN(MID(N38,1,SEARCH("_",N38)-1))) -> 10.121.19.132 | AF38: =TRIM(CLEAN(MID(O38,1,SEARCH("_",O38)-1))) -> 10.121.99.158 | AG38: =MID(N38,AA38+1,AB38-AA38-1) -> MAKARPURA | AH38: =MID(O38,AC38+1,AD38-AC38-1) -> MGVCL TARSLI | AI38: =RIGHT(N38,LEN(N38)-SEARCH("\",N38)) -> S4P6 | AJ38: =RIGHT(O38,LEN(O38)-SEARCH("\",O38)) -> S1P6 | AK38: =IFERROR(VLOOKUP(Z38,'PASTE-DL-ALARMS'!$Q$10:$W$2200,7,FALSE),"") | AL38: =IFERROR(VLOOKUP(Z38,'PASTE-DL-ALARMS'!$Q$10:$W$2200,3,FALSE),"") | AM38: =CONCATENATE(AE38,"_",AG38,"_",AI38) -> 10.121.19.132_MAKARPURA_S4P6 | AN38: =CONCATENATE(AF38,"_",AH38,"_",AJ38) -> 10.121.99.158_MGVCL TARSLI_S1P6 | AO38: =$AL$3-AK38 -> #VALUE! | AP38: =IFERROR(VLOOKUP(Z38,'PASTE-DL-ALARMS'!$Q$10:$Z$2800,8,FALSE),"")
C39: =IF(D39="Critical",MAX($C$8:C38)+1,"") | D39: =TRIM(CLEAN(P39)) -> - | E39: =VLOOKUP('PASTE-DOWN-DL'!F39,'SSA-CODE'!$D$4:$E$56,2,FALSE) -> BUJ | F39: =TRIM(CLEAN(SUBSTITUTE(G39,CHAR(160)," "))) -> SSA BUJ | G39: =MID(I39,1,SEARCH("-",I39)-1) -> SSA BUJ | H39: 30 | I39: SSA BUJ-10.121.24.66-Mundra Rd TE_6/3-10.121.17.66-Bhuj2(GNE)_3/4 | J39: Fiber | K39: GE | L39: Eth | M39: BI-DIR | N39: 10.121.24.66_MBM Bhuj B2_TN725B_GJ_SSA BUJ_PH2\S6P3 | O39: 10.121.17.66_BHUJ2(GNE)_TN725B_WTR_RJ_PH1\S3P4 | P39: - | Q39: 91 | R39: 100 | S39: GCS_ID-0014961 | T39: 60070238 | U39: Bhuj_SSA | V39: 1.0 | W39: 2022/02/25,13:59:34 | X39: 2026/04/18,11:46:55 | Z39: =TRIM(CLEAN(I39)) -> SSA BUJ-10.121.24.66-Mundra Rd TE_6/3-10.121.17.66-Bhuj2(GNE)_3/4 | AA39: =SEARCH("_",N39) -> 14 | AB39: =SEARCH("_TN7",N39) -> 26 | AC39: =SEARCH("_",O39) -> 14 | AD39: =SEARCH("_TN7",O39) -> 25 | AE39: =TRIM(CLEAN(MID(N39,1,SEARCH("_",N39)-1))) -> 10.121.24.66 | AF39: =TRIM(CLEAN(MID(O39,1,SEARCH("_",O39)-1))) -> 10.121.17.66 | AG39: =MID(N39,AA39+1,AB39-AA39-1) -> MBM Bhuj B2 | AH39: =MID(O39,AC39+1,AD39-AC39-1) -> BHUJ2(GNE) | AI39: =RIGHT(N39,LEN(N39)-SEARCH("\",N39)) -> S6P3 | AJ39: =RIGHT(O39,LEN(O39)-SEARCH("\",O39)) -> S3P4 | AK39: =IFERROR(VLOOKUP(Z39,'PASTE-DL-ALARMS'!$Q$10:$W$2200,7,FALSE),"") | AL39: =IFERROR(VLOOKUP(Z39,'PASTE-DL-ALARMS'!$Q$10:$W$2200,3,FALSE),"") | AM39: =CONCATENATE(AE39,"_",AG39,"_",AI39) -> 10.121.24.66_MBM Bhuj B2_S6P3 | AN39: =CONCATENATE(AF39,"_",AH39,"_",AJ39) -> 10.121.17.66_BHUJ2(GNE)_S3P4 | AO39: =$AL$3-AK39 -> #VALUE! | AP39: =IFERROR(VLOOKUP(Z39,'PASTE-DL-ALARMS'!$Q$10:$Z$2800,8,FALSE),"")
C40: =IF(D40="Critical",MAX($C$8:C39)+1,"") | D40: =TRIM(CLEAN(P40)) -> - | E40: =VLOOKUP('PASTE-DOWN-DL'!F40,'SSA-CODE'!$D$4:$E$56,2,FALSE) -> BUJ | F40: =TRIM(CLEAN(SUBSTITUTE(G40,CHAR(160)," "))) -> SSA BUJ | G40: =MID(I40,1,SEARCH("-",I40)-1) -> SSA BUJ | H40: 31 | I40: SSA BUJ-10.121.96.165-AIR_Kukma_1/5-10.121.24.69-Kukma_4/2 | J40: Fiber | K40: GE | L40: Eth | M40: BI-DIR | N40: 10.121.96.165_AIR KUKMA_TN703B_GJ_SSA BUJ_PH3\S1P5 | O40: 10.121.24.69_KUKMA_TN705B_GJ_SSA BUJ_PH2\S4P2 | P40: - | Q40: 7 | R40: 88 | S40: GUJ_GCS_ID_0043120 | T40: 200800788 | U40: BHUJ_SSA | V40: 1.0 | W40: 2025/07/12,23:58:05 | X40: 2026/04/18,11:47:30 | Z40: =TRIM(CLEAN(I40)) -> SSA BUJ-10.121.96.165-AIR_Kukma_1/5-10.121.24.69-Kukma_4/2 | AA40: =SEARCH("_",N40) -> 15 | AB40: =SEARCH("_TN7",N40) -> 25 | AC40: =SEARCH("_",O40) -> 14 | AD40: =SEARCH("_TN7",O40) -> 20 | AE40: =TRIM(CLEAN(MID(N40,1,SEARCH("_",N40)-1))) -> 10.121.96.165 | AF40: =TRIM(CLEAN(MID(O40,1,SEARCH("_",O40)-1))) -> 10.121.24.69 | AG40: =MID(N40,AA40+1,AB40-AA40-1) -> AIR KUKMA | AH40: =MID(O40,AC40+1,AD40-AC40-1) -> KUKMA | AI40: =RIGHT(N40,LEN(N40)-SEARCH("\",N40)) -> S1P5 | AJ40: =RIGHT(O40,LEN(O40)-SEARCH("\",O40)) -> S4P2 | AK40: =IFERROR(VLOOKUP(Z40,'PASTE-DL-ALARMS'!$Q$10:$W$2200,7,FALSE),"") | AL40: =IFERROR(VLOOKUP(Z40,'PASTE-DL-ALARMS'!$Q$10:$W$2200,3,FALSE),"") | AM40: =CONCATENATE(AE40,"_",AG40,"_",AI40) -> 10.121.96.165_AIR KUKMA_S1P5 | AN40: =CONCATENATE(AF40,"_",AH40,"_",AJ40) -> 10.121.24.69_KUKMA_S4P2 | AO40: =$AL$3-AK40 -> #VALUE! | AP40: =IFERROR(VLOOKUP(Z40,'PASTE-DL-ALARMS'!$Q$10:$Z$2800,8,FALSE),"")
C41: =IF(D41="Critical",MAX($C$8:C40)+1,"") | D41: =TRIM(CLEAN(P41)) -> - | E41: =VLOOKUP('PASTE-DOWN-DL'!F41,'SSA-CODE'!$D$4:$E$56,2,FALSE) -> AHD | F41: =TRIM(CLEAN(SUBSTITUTE(G41,CHAR(160)," "))) -> SSA AM | G41: =MID(I41,1,SEARCH("-",I41)-1) -> SSA AM | H41: 32 | I41: SSA AM-10.121.18.233-Mahatma_2/5-10.121.18.204-5ESS GNR_3/4 | J41: Fiber | K41: GE | L41: Eth | M41: BI-DIR | N41: 10.121.18.204_5ESS-GNR_TN725B_GJ_SSA AM_PH1\S3P4 | O41: 10.121.18.233_MAHATMA_TN703B_GJ_SSA AM_PH3\S2P5 | P41: - | Q41: 42 | R41: 100 | S41: Ahmedabad SSA GCS ID 25348 | T41: 200800716 | U41: Ahmedabad SSA GCS ID 25348 | V41: 1.0 | W41: 2023/08/26,20:26:05 | X41: 2026/04/18,11:47:59 | Z41: =TRIM(CLEAN(I41)) -> SSA AM-10.121.18.233-Mahatma_2/5-10.121.18.204-5ESS GNR_3/4 | AA41: =SEARCH("_",N41) -> 15 | AB41: =SEARCH("_TN7",N41) -> 24 | AC41: =SEARCH("_",O41) -> 15 | AD41: =SEARCH("_TN7",O41) -> 23 | AE41: =TRIM(CLEAN(MID(N41,1,SEARCH("_",N41)-1))) -> 10.121.18.204 | AF41: =TRIM(CLEAN(MID(O41,1,SEARCH("_",O41)-1))) -> 10.121.18.233 | AG41: =MID(N41,AA41+1,AB41-AA41-1) -> 5ESS-GNR | AH41: =MID(O41,AC41+1,AD41-AC41-1) -> MAHATMA | AI41: =RIGHT(N41,LEN(N41)-SEARCH("\",N41)) -> S3P4 | AJ41: =RIGHT(O41,LEN(O41)-SEARCH("\",O41)) -> S2P5 | AK41: =IFERROR(VLOOKUP(Z41,'PASTE-DL-ALARMS'!$Q$10:$W$2200,7,FALSE),"") | AL41: =IFERROR(VLOOKUP(Z41,'PASTE-DL-ALARMS'!$Q$10:$W$2200,3,FALSE),"") | AM41: =CONCATENATE(AE41,"_",AG41,"_",AI41) -> 10.121.18.204_5ESS-GNR_S3P4 | AN41: =CONCATENATE(AF41,"_",AH41,"_",AJ41) -> 10.121.18.233_MAHATMA_S2P5 | AO41: =$AL$3-AK41 -> #VALUE! | AP41: =IFERROR(VLOOKUP(Z41,'PASTE-DL-ALARMS'!$Q$10:$Z$2800,8,FALSE),"")
C42: =IF(D42="Critical",MAX($C$8:C41)+1,"") | D42: =TRIM(CLEAN(P42)) -> - | E42: =VLOOKUP('PASTE-DOWN-DL'!F42,'SSA-CODE'!$D$4:$E$56,2,FALSE) -> WTR RJ | F42: =TRIM(CLEAN(SUBSTITUTE(G42,CHAR(160)," "))) -> WTR RJ | G42: =MID(I42,1,SEARCH("-",I42)-1) -> WTR RJ | H42: 33 | I42: WTR RJ-10.121.17.66-Bhuj2(GNE)_4/7-10.121.17.65-Bhuj1(GNE)_4/7 | J42: Twisted-Pair | K42: GE | L42: Eth | M42: BI-DIR | N42: 10.121.17.66_BHUJ2(GNE)_TN725B_WTR_RJ_PH1\S4P7 | O42: 10.121.17.65_BHUJ1(GNE)_TN725B_WTR_RJ_PH1\S4P7 | P42: - | Q42: 68 | R42: 100 | T42: 200303555 | V42: 1.0 | W42: 2018/08/21,15:25:10 | X42: 2026/04/18,11:48:32 | Z42: =TRIM(CLEAN(I42)) -> WTR RJ-10.121.17.66-Bhuj2(GNE)_4/7-10.121.17.65-Bhuj1(GNE)_4/7 | AA42: =SEARCH("_",N42) -> 14 | AB42: =SEARCH("_TN7",N42) -> 25 | AC42: =SEARCH("_",O42) -> 14 | AD42: =SEARCH("_TN7",O42) -> 25 | AE42: =TRIM(CLEAN(MID(N42,1,SEARCH("_",N42)-1))) -> 10.121.17.66 | AF42: =TRIM(CLEAN(MID(O42,1,SEARCH("_",O42)-1))) -> 10.121.17.65 | AG42: =MID(N42,AA42+1,AB42-AA42-1) -> BHUJ2(GNE) | AH42: =MID(O42,AC42+1,AD42-AC42-1) -> BHUJ1(GNE) | AI42: =RIGHT(N42,LEN(N42)-SEARCH("\",N42)) -> S4P7 | AJ42: =RIGHT(O42,LEN(O42)-SEARCH("\",O42)) -> S4P7 | AK42: =IFERROR(VLOOKUP(Z42,'PASTE-DL-ALARMS'!$Q$10:$W$2200,7,FALSE),"") | AL42: =IFERROR(VLOOKUP(Z42,'PASTE-DL-ALARMS'!$Q$10:$W$2200,3,FALSE),"") | AM42: =CONCATENATE(AE42,"_",AG42,"_",AI42) -> 10.121.17.66_BHUJ2(GNE)_S4P7 | AN42: =CONCATENATE(AF42,"_",AH42,"_",AJ42) -> 10.121.17.65_BHUJ1(GNE)_S4P7 | AO42: =$AL$3-AK42 -> #VALUE! | AP42: =IFERROR(VLOOKUP(Z42,'PASTE-DL-ALARMS'!$Q$10:$Z$2800,8,FALSE),"")
C43: =IF(D43="Critical",MAX($C$8:C42)+1,"") | D43: =TRIM(CLEAN(P43)) -> - | E43: =VLOOKUP('PASTE-DOWN-DL'!F43,'SSA-CODE'!$D$4:$E$56,2,FALSE) -> GDR | F43: =TRIM(CLEAN(SUBSTITUTE(G43,CHAR(160)," "))) -> SSA GDH | G43: =MID(I43,1,SEARCH("-",I43)-1) -> SSA GDH | H43: 34 | I43: SSA GDH-10.121.19.1-Dahod TE(GNE)_4/5-10.121.19.25-Bhurani_1/5 | J43: Fiber | K43: GE | L43: Eth | M43: BI-DIR | N43: 10.121.19.25_BHURANI_TN703B_GJ_SSA GDH_PH3\S1P5 | O43: 10.121.19.1_Dahod TE(GNE)_TN725B_GJ_SSA GDH_PH2\S4P5 | P43: - | Q43: 46 | R43: 100 | T43: Vikas | V43: 1.0 | W43: 2019/07/03,13:25:11 | X43: 2026/04/18,11:49:16 | Z43: =TRIM(CLEAN(I43)) -> SSA GDH-10.121.19.1-Dahod TE(GNE)_4/5-10.121.19.25-Bhurani_1/5 | AA43: =SEARCH("_",N43) -> 14 | AB43: =SEARCH("_TN7",N43) -> 22 | AC43: =SEARCH("_",O43) -> 13 | AD43: =SEARCH("_TN7",O43) -> 27 | AE43: =TRIM(CLEAN(MID(N43,1,SEARCH("_",N43)-1))) -> 10.121.19.25 | AF43: =TRIM(CLEAN(MID(O43,1,SEARCH("_",O43)-1))) -> 10.121.19.1 | AG43: =MID(N43,AA43+1,AB43-AA43-1) -> BHURANI | AH43: =MID(O43,AC43+1,AD43-AC43-1) -> Dahod TE(GNE) | AI43: =RIGHT(N43,LEN(N43)-SEARCH("\",N43)) -> S1P5 | AJ43: =RIGHT(O43,LEN(O43)-SEARCH("\",O43)) -> S4P5 | AK43: =IFERROR(VLOOKUP(Z43,'PASTE-DL-ALARMS'!$Q$10:$W$2200,7,FALSE),"") | AL43: =IFERROR(VLOOKUP(Z43,'PASTE-DL-ALARMS'!$Q$10:$W$2200,3,FALSE),"") | AM43: =CONCATENATE(AE43,"_",AG43,"_",AI43) -> 10.121.19.25_BHURANI_S1P5 | AN43: =CONCATENATE(AF43,"_",AH43,"_",AJ43) -> 10.121.19.1_Dahod TE(GNE)_S4P5 | AO43: =$AL$3-AK43 -> #VALUE! | AP43: =IFERROR(VLOOKUP(Z43,'PASTE-DL-ALARMS'!$Q$10:$Z$2800,8,FALSE),"")
...

Sheet PASTE-DL-ALARMS
Q1: 14 | R1: 15 | S1: 16 | T1: 17 | U1: 18 | V1: 19 | W1: 20 | X1: 21 | Y1: 22 | Z1: 23 | AA1: 24 | AB1: 25 | AC1: 26
A2: Don't do any change in GREY colored cells | I2: Paste here --- > CPAN DL Alarms | Q2: 1 | R2: 2 | S2: 3 | T2: 4 | U2: 5 | V2: 6 | W2: 7 | X2: 8 | Y2: 9 | Z2: 10 | AA2: 11 | AB2: 12 | AC2: 13
I4: Alarms | J4: =MAX(D10:D1800) -> 88 | L4: =TEXT(TODAY(),"yyyy/mm/dd") -> 2026/05/15 | M4: Choose Days DOWN | N4: 1
D8: 0 | F8: SN | G8: Alarm ID | H8: Severity | I8: Category | J8: Service Type | K8: Service ID | L8: Create Time | M8: Ack User | N8: Ack Time | O8: Description | P8: Memo
D9: 0 | E9: SN | F9: SN | G9: Alarm ID | H9: Severity | I9: Category | J9: Service Type | K9: Service ID | L9: Create Time | M9: Ack User | N9: Ack Time | O9: Description | P9: Memo | Q9: DL name | R9: Full Date | S9: time | T9: Date | U9: Month | V9: Year | W9: Date -MIX | X9: Date-time mix
D10: =IF(F10="","",MAX($D$8:D9)+1) -> 1 | E10: 1 | F10: 2586278 | G10: Signal_DL_Failure | H10: Critical | I10: QoS | J10: DL | K10: \\\DL=SSA BCH-10.121.16.2-Ankleshwar_S5P1-10.121.100.10-Pipodara_S4P1 | L10: 2026/05/15,16:23:40 | N10: ----/--/--,--:--:-- | O10: Digital Link Layer Failure | Q10: =TRIM(CLEAN(MID(K10,SEARCH("=",K10)+1,LEN(K10)-SEARCH("=",K10)))) -> SSA BCH-10.121.16.2-Ankleshwar_S5P1-10.121.100.10-Pipodara_S4P1 | R10: =TRIM(CLEAN(LEFT(L10,SEARCH(",",L10)-1))) -> 2026/05/15 | S10: =TRIM(CLEAN(RIGHT(L10,LEN(L10)-SEARCH(",",L10)))) -> 16:23:40 | T10: =RIGHT(R10,2) -> 15 | U10: =MID(R10,6,2) -> 05 | V10: =LEFT(R10,4) -> 2026 | W10: =CONCATENATE(T10,"-",U10,"-",V10) -> 15-05-2026 | X10: =L10 -> 2026/05/15,16:23:40
D11: =IF(F11="","",MAX($D$8:D10)+1) -> 2 | E11: 2 | F11: 2586211 | G11: Signal_DL_Failure | H11: Critical | I11: QoS | J11: DL | K11: \\\DL=WTR AM-10.121.26.67-Piplod_4/6-10.121.26.73-Devgadh Baria_3/2 | L11: 2026/05/15,16:23:36 | N11: ----/--/--,--:--:-- | O11: Digital Link Layer Failure | Q11: =TRIM(CLEAN(MID(K11,SEARCH("=",K11)+1,LEN(K11)-SEARCH("=",K11)))) -> WTR AM-10.121.26.67-Piplod_4/6-10.121.26.73-Devgadh Baria_3/2 | R11: =TRIM(CLEAN(LEFT(L11,SEARCH(",",L11)-1))) -> 2026/05/15 | S11: =TRIM(CLEAN(RIGHT(L11,LEN(L11)-SEARCH(",",L11)))) -> 16:23:36 | T11: =RIGHT(R11,2) -> 15 | U11: =MID(R11,6,2) -> 05 | V11: =LEFT(R11,4) -> 2026 | W11: =CONCATENATE(T11,"-",U11,"-",V11) -> 15-05-2026 | X11: =L11 -> 2026/05/15,16:23:36
D12: =IF(F12="","",MAX($D$8:D11)+1) -> 3 | E12: 3 | F12: 2586211 | G12: Signal_DL_Failure | H12: Critical | I12: QoS | J12: DL | K12: \\\DL=WTR AM-10.121.26.67-Piplod_4/6-10.121.26.73-Devgadh Baria_3/2 | L12: 2026/05/15,16:23:36 | N12: ----/--/--,--:--:-- | O12: Digital Link Layer Failure | Q12: =TRIM(CLEAN(MID(K12,SEARCH("=",K12)+1,LEN(K12)-SEARCH("=",K12)))) -> WTR AM-10.121.26.67-Piplod_4/6-10.121.26.73-Devgadh Baria_3/2 | R12: =TRIM(CLEAN(LEFT(L12,SEARCH(",",L12)-1))) -> 2026/05/15 | S12: =TRIM(CLEAN(RIGHT(L12,LEN(L12)-SEARCH(",",L12)))) -> 16:23:36 | T12: =RIGHT(R12,2) -> 15 | U12: =MID(R12,6,2) -> 05 | V12: =LEFT(R12,4) -> 2026 | W12: =CONCATENATE(T12,"-",U12,"-",V12) -> 15-05-2026 | X12: =L12 -> 2026/05/15,16:23:36
